Workbook
Name ChartItem: OFFSET([1]③공정조회!$X$14,0,0,MAX(1,COUNTA([1]③공정조회!$X$14:$X$63)),1)
Name ChartItemVal: OFFSET([1]③공정조회!$Y$14,0,0,MAX(1,COUNTA([1]③공정조회!$X$14:$X$63)),1)
Name ChartWork: OFFSET([1]③공정조회!$U$14,0,0,MAX(1,COUNTA([1]③공정조회!$U$14:$U$63)),1)
Name ChartWorkVal: OFFSET([1]③공정조회!$V$14,0,0,MAX(1,COUNTA([1]③공정조회!$U$14:$U$63)),1)

Sheet SIF DB
A1: 순 | B1: 공종 | C1: 작업명 | D1: 단위작업명 | E1: KOEN 공정 | F1: 기인물 분류(VlookUp) | G1: 기인물 | H1: 구분(12대 기인물 선택) | I1: 위험도 순위 (~12위) | J1: 3년간 사고비중(19~21년) | K1: 재해년월 추출(함수) | L1: 재해년월추출 | M1: 재해월추출 | N1: 혹서기 | O1: 재해형태 | P1: 재해개요 : 재해시기 추출 | Q1: 재해유발요인 재해형태 추출(떨어짐, 추락 등 >> 맨오른쪽 2글자) | R1: 위험성 감소대책(예시)
A2: 11 | B2: 11. 기타 토목공사 | C2: 11.1 부대 토목 작업 | D2: 11.1.1 부대토목 옹벽시공 | E2: YES | F2: 각재(파이프,강관,합판) | G2: 각재(파이프,강관,합판) | H2: 해당없음 | I2: 해당없음 | J2: 해당없음 | K2: 2015년 12월 | L2: 42339 | M2: 12 | N2: 혹한기 | O2: 맞음 | P2: 2015년 12월경 군부대 방호문 설치공사에서 재해자가 보강초 벽체에 각재를 대어 기울어진 보강토 블록 벽체를 바로 세우는 작업 중 굴착기 버킷으로 힘을 가하다 각재가 갑자기 이탈되면서 힘을 가하던 굴착기 버킷에 맞아 사망 | Q2: 보강토 벽체에 각재를 대어 굴삭기 버켓으로 힘을 가하던 과정에서 각재가 갑자기 이탈되면서 타격함 | R2: ▶ 굴삭기 작업시 토사의 굴착, 절토 등 장비용도에 맞게 사용 ▶ 건설기계 제원, 성능, 작업반경 등을 고려하여 작업
A3: 11 | B3: 11. 기타 토목공사 | C3: 11.4 맨홀 및 관부설작업 | D3: 11.4.1 맨홀 및 관부설 굴착 | E3: YES | F3: 각재(파이프,강관,합판) | G3: 각재(파이프,강관,합판) | H3: 해당없음 | I3: 해당없음 | J3: 해당없음 | K3: 2020년 6월경 | L3: 43983 | M3: 6 | N3: 혹서기 | O3: 깔림 뒤집힘 | P3: 2020년 6월경 OOO도 OO군 OOO면 소재 (주)OOOO 자재 야적장에서 재해자가 화물차량(25.5톤) 높이 약 1.7 m 적재함 위에서 크레인(10톤)으로 인양된 강관파이프(하수관거*)를 차량에 적재하던 중, 3단으로 불안정하게 적재된 강관파이프가 붕괴되어 재해자가 야적장 바닥으로 떨어졌으며, 이때 차량 적재함에서 낙하한 강관파이프(약 390kg)에 깔려서 사망한 재해임._x000D_ | Q3: 크레인으로 인양된 강관파이프를 차량에 적재하던 중, 3단으로 불안정하게 적재된 강관파이프가 붕괴되어 강관파이프에 깔림 | R3: ▶ 자재를 야적하는 경우 평탄한 곳에 적재하며 구름방지조치 실시 ▶ 경사면에서 흄관을 고정하기 위해 쐐기 등을 이용 ▶ 강관파이프를 3단이상 등 과도하게 적재 금지
A4: 11 | B4: 11. 기타 토목공사 | C4: 11.4 맨홀 및 관부설작업 | D4: 11.4.2 맨홀 및 관 부설 | E4: YES | F4: 각재(파이프,강관,합판) | G4: 각재(파이프,강관,합판) | H4: 해당없음 | I4: 해당없음 | J4: 해당없음 | K4: 2021년 4월경 | L4: 44287 | M4: 4 | N4: - | O4: 맞음 | P4: 2021년 4월경 OOO도 OO시 OO동 소재 OOOO(주) OOOO 노후 상수관망 정비 공사 현장에서 화물차에 적재되어 있는 주철관을 슬링벨트로 묶어 하역하는 준비 작업 중 주철관이 슬링벨트 밖으로 이탈하며 재해자를 덮쳐 약 1.85m 높이의 차량 측면에서 바닥으로 떨어져 사망한 재해임 | Q4: 관로 정비 공사 현장에서 화물차에 적재되어 있는 주철관을 슬링벨트로 묶어 하역하는 준비 작업 중 주철관이 슬링벨트 밖으로 이탈하며 재해자를 덮침 | R4: ▶ 화물적재 작업 시 최대 적재량 및 한쪽으로 치우치지 않은 적재 등의 조치 준수 ▶ 로프 풀기 작업 전 적재함 주변에 근로자의 통행을 통제한 뒤 하역작업 실시
A5: 12 | B5: 12. 공통공사 | C5: 12.1 철거, 해체 | D5: 12.1.1 철거 및 해체 | E5: YES | F5: 각재(파이프,강관,합판) | G5: 각재(파이프,강관,합판) | H5: 해당없음 | I5: 해당없음 | J5: 해당없음 | K5: 2017년 2월경 | L5: 42767 | M5: 2 | N5: 혹한기 | O5: 깔림 뒤집힘 | P5: 2017년 2월경 OO(주)가 시공하는 OO신축공사 현장에서 철근콘크리트공사 협력업체인 (주)OO건설 소속 재해자가 방음벽 Post(지지대) 해체작업을 하다가 중심을 잃은 방음벽 Post가 재해자 쪽으로 넘어지면서 재해자를 타격하여 사망 | Q5: 해체작업을 하던 중 방음벽 및 배관 등 해체물이 재해자쪽으로 전도되어 맞음, 깔림 | R5: ▶ 해체물, 자재 등 현장 내 존치할 경우 전도방지조치 실시 ▶ 건축물의 해체 작업시 작업반경 내 작업자의 출입 금지조치
A6: 12 | B6: 12. 공통공사 | C6: 12.2 안전가시설 작업 | D6: 12.2.3 안전가시설(비계) | E6: YES | F6: 각재(파이프,강관,합판) | G6: 각재(파이프,강관,합판) | H6: 해당없음 | I6: 해당없음 | J6: 해당없음 | K6: 2017년 2월경 | L6: 42767 | M6: 2 | N6: 혹한기 | O6: 떨어짐 | P6: 2017년 2월경 근린생활시설 신축공사 현장에서 재해자가 2층 외벽 비계 발판 4단위에서 강관 파이프를 상부 발판으로 이동 중 실족 지상 7m 아래 바닥으로 떨어져 사망 | Q6: 가설 울타리의 강관지지대 해체작업 중 기 해체한 수평재를 밟고 바닥으로 추락 | R6: ▶ 비계 해체 작업 등 고소작업 시, 강관지지대로 올라가 작업하는 행위름 금지하고 이동식비계 또는 고소작업대를 사용하여 작업하도록 조치 ▶ 비계 해체 작업 등 고소작업 시, 해체장소가 협소하거나 지형이 가파름 등의 이유로 이동식비계, 고소작업대 등을 사용할 수 없을 경우, 굴삭기 등 건설장비를 사용하여 인명피해가 없도록 조치 후 작업 진행
A7: 12 | B7: 12. 공통공사 | C7: 12.2 안전가시설 작업 | D7: 12.2.3 안전가시설(비계) | E7: YES | F7: 각재(파이프,강관,합판) | G7: 각재(파이프,강관,합판) | H7: 해당없음 | I7: 해당없음 | J7: 해당없음 | K7: 2018년 1월경 | L7: 43101 | M7: 1 | N7: 혹한기 | O7: 떨어짐 | P7: 2018년 1월경 ㈜OO지점이 시공중인 (주)OOO코리아 신사옥 건설공사 현장에서 협력업체 OO건설 소속 재해자(비계공)가 전면부 지상4층 외부 강관비계 작업발판 상부에서 비계기둥 연장설치 작업 중 쓰러지는 강관파이프(6m, 약 15.78kg)와 함께 지상1층 바닥(H≒15m)으로 떨어져 사망 | Q7: 추락방지조치 미흡한 상태에서 지상층 전면부 철골기둥의 비계 외측 수직 강관설치작업을 도와주기 위해 비계 작업발판 상부에서 외측 수직강관 설치작업 중 쓰러지는 강관파이프와 함께 지면으로 추락 | R7: ▶ 추락 위험이 있는 작업 시, 안전방망, 안전난간, 안전대 부착설비 등 안전방호조치 실시 ▶ 작업 전 안전대 지급 및 착용, 체결상태 관리감독자 확인 철저
A8: 12 | B8: 12. 공통공사 | C8: 12.2 안전가시설 작업 | D8: 12.2.3 안전가시설(비계) | E8: YES | F8: 각재(파이프,강관,합판) | G8: 각재(파이프,강관,합판) | H8: 해당없음 | I8: 해당없음 | J8: 해당없음 | K8: 2018년 8월경 | L8: 43313 | M8: 8 | N8: 혹서기 | O8: 떨어짐 | P8: 2018년 8월경 OO 지식산업센터 신축공사 현장에서 재해자가 현장 대지경계선에 설치되어 있던 가설 울타리의 강관지지대 해체를 위해 하단 수평재를 밟고 서서 상단 수평재를 해체하던 중 해체한 수평재와 함께 약 3.5m 바닥에 추락하여 사망 | Q8: 가설 울타리의 강관지지대 해체작업 중 기 해체한 수평재를 밟고 바닥으로 추락 | R8: ▶ 비계 해체 작업 등 고소작업 시, 강관지지대로 올라가 작업하는 행위름 금지하고 이동식비계 또는 고소작업대를 사용하여 작업하도록 조치 ▶ 비계 해체 작업 등 고소작업 시, 해체장소가 협소하거나 지형이 가파름 등의 이유로 이동식비계, 고소작업대 등을 사용할 수 없을 경우, 굴삭기 등 건설장비를 사용하여 인명피해가 없도록 조치 후 작업 진행
A9: 12 | B9: 12. 공통공사 | C9: 12.2 안전가시설 작업 | D9: 12.2.3 안전가시설(비계) | E9: YES | F9: 각재(파이프,강관,합판) | G9: 각재(파이프,강관,합판) | H9: 해당없음 | I9: 해당없음 | J9: 해당없음 | K9: 2019년 1월경 | L9: 43466 | M9: 1 | N9: 혹한기 | O9: 맞음 | P9: 2019년 1월경 OO건설의 지식산업센터 신축공사 현장의 주차타워 내부 비계 위에서 재해자 2명이 타워크레인으로 인양되는 비계재료(강관, 클램프 등)를 받기 위해 신호 및 대기하던 중 지상 14층 주차타워 개구부 단부에 설치된 안전난간에 인양하물이 걸려 기울어지면서 강관파이프 등 비계재료가 줄걸이에서 이탈되어 약 26.8m 아래에 있던 재해자 2명이 떨어지는 비계 재료에 맞거나 피하던 중 지하바닥 등으로 추락하여 사망 | Q9: 적재된 단관비계다발 하역을 위한 화물고정용 섬유벨트 해체 후 비계다발이 차량하부로 낙하하며 근로자 강타 | R9: ▶ 화물적재 작업 시 최대 적재량 및 한쪽으로 치우치지 않은 적재 등의 조치 준수 ▶ 로프 풀기 작업 시 적재함의 화물이 떨어질 위험이 없음을 확인 호 주치 실시
A10: 12 | B10: 12. 공통공사 | C10: 12.2 안전가시설 작업 | D10: 12.2.3 안전가시설(비계) | E10: YES | F10: 각재(파이프,강관,합판) | G10: 각재(파이프,강관,합판) | H10: 해당없음 | I10: 해당없음 | J10: 해당없음 | K10: 2020년 8월경 | L10: 44044 | M10: 8 | N10: 혹서기 | O10: 맞음 | P10: 2020년 8월경 OO공사 현장에서 재해자가 카고트럭 적재함에 적재된 단관비계 다발을 하역하기 위해 짐걸이로 사용했던 화물고정용 섬유벨트(자동바)를 해체하는 순간 상단에 적재되어 있던 단관비계 다발이 차량하부로 떨어지면서(H≒2.3m) 재해자의 상반신(두부 및 흉부)이 충돌되어 사망 | Q10: 적재된 단관비계다발 하역을 위한 화물고정용 섬유벨트 해체 후 비계다발이 차량하부로 낙하하며 근로자 강타 | R10: ▶ 화물적재 작업 시 최대 적재량 및 한쪽으로 치우치지 않은 적재 등의 조치 준수 ▶ 로프 풀기 작업 시 적재함의 화물이 떨어질 위험이 없음을 확인 호 주치 실시
A11: 12 | B11: 12. 공통공사 | C11: 12.2 안전가시설 작업 | D11: 12.2.3 안전가시설(비계) | E11: YES | F11: 각재(파이프,강관,합판) | G11: 각재(파이프,강관,합판) | H11: 해당없음 | I11: 해당없음 | J11: 해당없음 | K11: 재해자가 카고트럭 | L11: X | M11: #VALUE! | N11: #VALUE! | O11: 맞음 | P11: 재해자가 카고트럭 상부에서 강관파이프 다발(중량≒630kg) 적재작업을 하는 중 굴착기 운전원의 오조작에 의해 붐대와 함께 강관파이프 다발이 회전하면서 재해자의 안면을 강타하여 사망 | Q11: 굴삭기 운전원의 오조작에 의해 붐대와 함께 강관파이프 다발이 회전하면서 안면을 강타 | R11: ▶ 관리감독자의 유해ㆍ위험방지 업무 철저 ▶ 중량물 취급시에는 운반 등의 작업에 있어서 계획서를 작업하고 그 계획에 따라 작업하도록 지시 ▶ 개인보호구 착용 및 관리 철저
A12: 12 | B12: 12. 공통공사 | C12: 12.5 양중기 작업 | D12: 12.5.4 양중기(윈치) | E12: YES | F12: 각재(파이프,강관,합판) | G12: 각재(파이프,강관,합판) | H12: 해당없음 | I12: 해당없음 | J12: 해당없음 | K12: 2018년 8월경 | L12: 43313 | M12: 8 | N12: 혹서기 | O12: 맞음 | P12: 2018년 8월경 OO건설에서 시공중인 OO초등학교 교실증축공사 현장에서 재해자가 1층 유치원 내부 벽체 내진보강을 위해 전동윈치에 ㄷ형강(149.45kg)을 걸어 인양하여 벽체에 세우던 중 벽체에 설치했던 전동윈치 걸이용 앵커볼트가 휘어지며 전동윈치가 탈락, 인양중인 ㄷ형강이 넘어져 재해자의 머리부위에 충돌해 사망 | Q12: 전동윈치에 ㄷ형강을 걸어 인양하여 벽체에 세우던 중, 전동윈치 걸이용 앵커볼트가 휘어지며 전동윈치가 탈락하여 ㄷ형강이 넘어져 근로자 두부 강타 | R12: ▶ 내진보강을 위한 ㄷ형강 설치 등 중량물 취급작업 시 제원파악이 가능한 출처분명의 앵커볼트를 사용 ▶ 천장부위 해체 시 ㄷ형강의 길이고려 등을 통해 양중 중 발생할 수 있는 낙하 및 전도 방지
A13: 12 | B13: 12. 공통공사 | C13: 12.7 기타(작업환경, 청소 등) | D13: 12.7.1 기타(작업환경, 청소 등) | E13: YES | F13: 각재(파이프,강관,합판) | G13: 각재(파이프,강관,합판) | H13: 해당없음 | I13: 해당없음 | J13: 해당없음 | K13: 2016년 6월경 | L13: 42522 | M13: 6 | N13: 혹서기 | O13: 맞음 | P13: 2016년 6월경 OO신축공사 현장에서 외부비계 상부에 있던(높이: 약 9m) 강관(길이: 약 2m, 무게: 약 5kg)이 떨어지면서 통로에서 자재정리를 하던 재해자의 머리에 맞아 사망 | Q13: 외부 비계 상부에 있던 강관이 떨어지면서 통로에서 자재정리하던 재해자 맞음 | R13: ▶ 비계, 작업발판 등에는 재료, 공구 등 낙하물 방치되지 않도록 관리 ▶ 근로자 개인보호구, 안전대 체결여부 점검 및 관리감독
A14: 12 | B14: 12. 공통공사 | C14: 12.7 기타(작업환경, 청소 등) | D14: 12.7.1 기타(작업환경, 청소 등) | E14: YES | F14: 각재(파이프,강관,합판) | G14: 각재(파이프,강관,합판) | H14: 해당없음 | I14: 해당없음 | J14: 해당없음 | K14: 2019년 6월경 | L14: 43617 | M14: 6 | N14: 혹서기 | O14: 떨어짐 | P14: 2019년 6월경 OO설치현장에서 재해자가 비닐하우스 활대(폭10m, 높이 7m, 개당중량 30kg, 재질: 강관파이프(Ø50mm))설치 준비작업 중 작업대로 사용하던 철재선반(가로 5.5mX 세로 4.5m, H≒2.6m)위에서 중심을 잃고 미끄러지며 지상1층 바닥(H≒2.6m)으로 추락하여 사망 | Q14: 비닐하우스 활대 설치 준비작업 중 작업대로 사용하던 철재선반 위에서 중심을 잃고 미끄러져 바닥으로 떨어짐 | R14: ▶ 불안전한 작업발판 위에서의 작업 금지
A15: 2 | B15: 2. 철근콘크리트공사 | C15: 2.1 거푸집 작업 | D15: 2.1.1 거푸집 자재반입, 가공, 운반 | E15: YES | F15: 각재(파이프,강관,합판) | G15: 각재(파이프,강관,합판) | H15: 해당없음 | I15: 해당없음 | J15: 해당없음 | K15: 2016년 4월경 | L15: 42461 | M15: 4 | N15: - | O15: 맞음(낙하물체) | P15: 2016년 4월경 OO건설 공사현장에서 재해자가 지하2층 슬라브 보 거푸집 제작작업 중, 타워크레인으로 인양 중이던 인양물(거푸집제작용 목재(약 0.5톤))이 작업부위 상부 약 4m위치로 접근하자, 작업부위와 인양물과의 충돌을 막기 위해 인양물 하부로 이동하는 순간, 인양물의 갑작스러운 떨어짐에 의하여 재해자가 맞음으로써 사망 | Q15: 타워크레인으로 거푸집 제작용 목재 등을 인양하던 중 미고정된 인양물의 인양물 낙하 | R15: ▶ 타워크레인 등 유해·위험한 기계·기구를 설치 시 안전인증을 받은 후 사용 ▶ 크레인 작업 시 낙하물에 의한 위험방지를 위해 사전에 근로자 출입 통제 ▶ 크레인 등을 사용하여 작업 시 작업 전 감속기 등 기계적 상태 점검 실시 후 작업
A16: 2 | B16: 2. 철근콘크리트공사 | C16: 2.1 거푸집 작업 | D16: 2.1.1 거푸집 자재반입, 가공, 운반 | E16: YES | F16: 각재(파이프,강관,합판) | G16: 각재(파이프,강관,합판) | H16: 해당없음 | I16: 해당없음 | J16: 해당없음 | K16: 2017년 12월 | L16: 43070 | M16: 12 | N16: 혹한기 | O16: 떨어짐 | P16: 2017년 12월경 OO단독주택 신축공사 현장에서 재해자가 외부비계 최상단과 건물사이에 각재(산승각)을 거치하고, 그 위에 거푸집자재(각관, 각재 등)를 적재하던 중 하부에 거치된 각재가 부러지며 상부에 적재된 자재가 무너져 내리며 약 9m아래로 추락하여 사망 | Q16: 작업발판 미설치한 상태에서 외부비계 최상단과 건물사이에 각재(산승각)을 거치하고, 그 위에 거푸집자재를 적재하던 중 하부에 거치된 각재가 부러지며 상부 적재된 자재 위에 서있던 근로자 추락 | R16: ▶ 추락 및 넘어질 위험이 있는 장소에 작업발판 및 안전난간 설치 ▶ 자재적재 작업을 위한 작업발판 설치 시 상부 적재하중을 고려하여 구조 검토 후 설치 ▶ 구조물 위에 자재적재가 어려워 거치목을 이용한 경우 최대적재하중에 대해 구조검토(휨, 전단) 실시
A17: 2 | B17: 2. 철근콘크리트공사 | C17: 2.1 거푸집 작업 | D17: 2.1.3 거푸집 동바리 해체 | E17: YES | F17: 각재(파이프,강관,합판) | G17: 각재(파이프,강관,합판) | H17: 해당없음 | I17: 해당없음 | J17: 해당없음 | K17: 2016년 4월경 | L17: 42461 | M17: 4 | N17: - | O17: 맞음 | P17: 2016년 4월경 OO건설 주식회사 OO신축공사 현장에서 협력업체 소속 재해자가 띠장 4단 사각강관 버팀보(350mm×350mm×9t, L=34m(11m+11m+12m), W=3.33t) 하부에서 거푸집 정리작업을 하던 중 해체 준비 중이던 사각강관 버팀보가 떨어지면서 머리부위를 맞아 사망 | Q17: 낙하물 위험구간 출입금지 미실시한 상태에서 띠장 버팀보 하부에서 거푸집 정리작업을 하던 중 해체 준비 중이던 사각강관 버팀보가 떨어지면서 머리에 맞음 | R17: ▶ 흙막이가시설 해체작업시 작업계획서 작성 및 준수 ▶ 버팀보도 등 인양 단위부재에 줄걸이를 체결한 후 볼트 제거, 인양 하는 등 단계적으로 작업 실시 ▶ 해체작업을 하는 장소에는 관계 근로자가 아닌 근로자 출입을 금지 철저
A18: 2 | B18: 2. 철근콘크리트공사 | C18: 2.1 거푸집 작업 | D18: 2.1.4 거푸집 동바리 인양 | E18: YES | F18: 각재(파이프,강관,합판) | G18: 각재(파이프,강관,합판) | H18: 해당없음 | I18: 해당없음 | J18: 해당없음 | K18: 2016년 7월경 | L18: 42552 | M18: 7 | N18: 혹서기 | O18: 떨어짐 | P18: 2016년 7월경 (주)00건설 00청사 신축공사 현장에서 재해자가 지하2층 저수조의 시스템동바리 상부 합판 위에서 해체된 거푸집동바리(무폼타이 거푸집, 51.8kg)를 작업용 로프에 묶어 하부 바닥으로 내리던 중 시스템동바리 상부 합판 위에 산재된 자재에 걸려 넘어지면서 하부 바닥(H≒3.3m)으로 추락하여 사망 | Q18: 추락 방지조치 미실시한 상태에서 지하층 저수조 시스템동바리 상부 합판 위에서 해체된 거푸집동바리를 작업용 로프에 묶어 하부 바닥으로 내리던 중 합판 주변 산재된 자재에 걸려 넘어지면서 근로자 추락 | R18: ▶ 추락위험이 있는 구간에는 추락방호망, 안전난간 설치 또는 및 안전대 착용후 작업 ▶ 낙하 및 전도 등의 위험구간에서 자재 인양 및 운반시 근로자 출입 통제
A19: 2 | B19: 2. 철근콘크리트공사 | C19: 2.3 철근 작업 | D19: 2.3.2 철근 가공 및 운반 | E19: YES | F19: 각재(파이프,강관,합판) | G19: 각재(파이프,강관,합판) | H19: 해당없음 | I19: 해당없음 | J19: 해당없음 | K19: 2016년 3월경 | L19: 42430 | M19: 3 | N19: - | O19: 떨어짐 | P19: 2016년 3월경 OO 건설공사 주택재개발 정비사업 현장의 3층 높이 엘리베이터 피트에서 재해자는 동료작업자가 작업발판용으로 매립된 철근을 산소용접기 및 핸드그라인더를 사용하여 절단하면, 절단된 철근을 받아 바깥 측에 적재, 정리 등의 작업 중 작업상의 이유로 엘리베이터 피트 내부로 진입한 재해자가 밟은 발판(합판)이 뒤집어지며 지하 2층 바닥으로 떨어져(H=11.2) 사망 | Q19: 고정되지 않은 작업발판을 밟고 작업 중 작업발판이 뒤집어지며 근로자 추락 | R19: ▶ 외부비계 상에서 작업 시 작업구간 전체에 걸쳐 작업발판 및 안전난간을 밀실하고 견고하게 설치 후 작업 실시 ▶ 작업발판 및 안전난간 설치가 곤란한 경우 안전대 걸 수 있는 안전대 부착설비 설치 ▶ 추락할 위험이 있는 장소에서 작업 시 개인보호구 착용 철저
A20: 2 | B20: 2. 철근콘크리트공사 | C20: 2.3 철근 작업 | D20: 2.3.2 철근 가공 및 운반 | E20: YES | F20: 각재(파이프,강관,합판) | G20: 각재(파이프,강관,합판) | H20: 해당없음 | I20: 해당없음 | J20: 해당없음 | K20: 2016년 8월경 | L20: 42583 | M20: 8 | N20: 혹서기 | O20: 떨어짐 | P20: 2016년 8월경 (주)OO종합건설에서 시공중인 OO공장신축공사 현장에서 재해자가 A동 지상2층 바닥 철근배근 작업을 위해 자재(철근-D13 L≒0.8m 약200EA)를 화물용 리프트 구간으로 운반작업 중, 받침판으로 사용한 각재(80mm×80mm×3,630mm) 4개중 3개가 파단되며, 지상1층 바닥(H≒5.8m)으로 떨어져 사망한 재해임 | Q20: 철근배근 작업을 위해 자재를 화물용 리프트 구간으로 운반작업 중, 받침판으로 사용한 각재가 파단되어 근로자 추락 | R20: ▶ 철근 등 중량물 적재 시 붕괴의 우려가 없는 받침판 위에 적재 또는 최대 적재하중을 초과하지 않는 선에서의 적재 ▶ 추락방지조치를 위한 안전대 부착설비 설치 및 안전대 착용
A21: 2 | B21: 2. 철근콘크리트공사 | C21: 2.3 철근 작업 | D21: 2.3.2 철근 가공 및 운반 | E21: YES | F21: 각재(파이프,강관,합판) | G21: 각재(파이프,강관,합판) | H21: 해당없음 | I21: 해당없음 | J21: 해당없음 | K21: 2017년 5월경 | L21: 42856 | M21: 5 | N21: - | O21: 절단 베임 찔림 | P21: 2017년 5월경 OO상가주택 신축공사 현장 1층 바닥에서 재해자가 동료작업자와 기둥 띠철근 조립 후, 후속작업을 위해 이동하던 중 바닥에 놓인 나무각재에 걸려 넘어지면서, 바닥에서 돌출된 벽체철근이 재해자 머리에 박혀 사망 | Q21: 기둥 띠철근 조립 후, 후속작업을 위해 이동하던 중 바닥에 놓인 각재에 걸려 넘어지면서 돌출된 벽체철근이 근로자 머리에 찔림 | R21: ▶ 현장 내부가 협소한 경우 별도의 자재보관 장소 확보 및 일부 자재만 내부에 순차적 반입으로 작업공간 및 이동통로 확보 ▶ 부득이하게 바닥에 각재와 같은 자재적치 시 상부에 근로자 전도방지를 위해 바닥으로부터 띄워 이동통로 설치 ▶ 이동구간에 돌출철근 등 재해우려 자재 돌출 시 철근 돌출부에 보호캡 설치
A22: 2 | B22: 2. 철근콘크리트공사 | C22: 2.4 콘크리트 작업 | D22: 2.4.2 콘크리트 타설 및 다짐 | E22: YES | F22: 각재(파이프,강관,합판) | G22: 각재(파이프,강관,합판) | H22: 해당없음 | I22: 해당없음 | J22: 해당없음 | K22: 2019년 3월경 | L22: 43525 | M22: 3 | N22: - | O22: 맞음 | P22: 2019년 3월경 OO건설(주) OO공동주택 신축공사 현장에서 협력업체 ㈜OO 소속 재해자(콘크리트공)가 주차장 누름콘크리트 타설 장소로 이동하기 위해 슬래브에 기대어 세운 목재각재를 밟고 올라가던 중 목재각재가 부러지며 복부를 맞아 복강내출혈 등이 발생하여 사망 | Q22: 콘크리트 타설 장소로 이동하던 중 이동통로가 확보되지 않은 상태에서 슬래브에 기대어 세운 목재각재를 밟고 올라가던 중 목재각재가 부러지며 근로자 복부를 강타 | R22: ▶ 작업장으로 통하는 장소 또는 작업장내에 통로의 주요 부분에 통로표시로 안전한 통행 보장 ▶ 작업여건에 의해 후속작업이 영향을 받은 경우 무리한 작업진행 지양
A23: 2 | B23: 2. 철근콘크리트공사 | C23: 2.4 콘크리트 작업 | D23: 2.4.3 콘크리트 양생 | E23: YES | F23: 각재(파이프,강관,합판) | G23: 각재(파이프,강관,합판) | H23: 해당없음 | I23: 해당없음 | J23: 해당없음 | K23: 2017년 12월 | L23: 43070 | M23: 12 | N23: 혹한기 | O23: 떨어짐 | P23: 2017년 12월 OO(주) 아파트 신축공사 현장에서, ㈜OO 소속 재해자가 지하주차장 지하1층 슬래브 거푸집 위에서 콘크리트 양생 보양천막 틀 설치작업 중, 몸의 중심을 잃고 지하 1층 바닥으로 떨어져(H≒4m) 사망 | Q23: 슬래브 거푸집 위에서 콘크리트 양생 보양천막 특 설치 작업 중 근로자가 몸의 중심을 잃고 안전난간이 설치되어 있지 않은 단부로 추락 | R23: ▶ 추락위험이 있는 개구부 주변에서 작업 시 단부에 안전난간 및 추락방호망 설치 ▶ 높이 2m 이상의 추락위험 장소에서 작업 시 안전대 부착설비 설치 및 안전대 착용 ▶ 개인보호구 지급 및 착용
... A40: 8 | B40: 8. 교량공사 | C40: 8.4 특수교량 작업 | D40: 8.4.1 특수교량(ILM 공법) | E40: NO | F40: 각재(파이프,강관,합판) | G40: 각재(파이프,강관,합판) | H40: 해당없음 | I40: 해당없음 | J40: 해당없음 | K40: 2017년 1월 | L40: 42736 | M40: 1 | N40: 혹한기 | O40: 깔림 뒤집힘 | P40: 2017년 1월 고속국도 건설공사에서 재해자가 교량 제작장 몰드커버 해체작업 중 거치되어 있던 몰드커버가 전도되면서 끼여 사망 | Q40: 레일기초와 교량거푸집 상부에 경사지게 거치된 몰드커버가 전도되며 기둥강관더미와 바닥 경사면 사이에 깔림 | R40: ▶ 몰드커버 해체작업 시, 사전에 적절한 작업순서를 수립 ▶ 크레인으로 인양작업 시, 작업반경 내 작업자 접근 금지조치
A41: 1 | B41: 1. 토공사 | C41: 1.1 굴착 작업 | D41: 1.1.1 굴착 장비반입 | E41: YES | F41: 개구부 | G41: 개구부(기타개구부) | H41: 12대 기인물 | I41: 1 | J41: 0.09 | K41: 2019년 3월경 | L41: 43525 | M41: 3 | N41: - | O41: 떨어짐 | P41: 2019년 3월경 OO공사에서 재해재가 장비 진입로를 위해 방호시설(나무합판, 석자재, 고체연료통)을 이동시키던 중 개구부에 빠져 약 4.7m 아래인 지하층 바닥으로 추락하여 사망 | Q41: 장비 진입을 위한 현장 정리 중 개구부를 인식하지 못하고 실족하여 추락 | R41: ▶ 추락 위험 구간 접근금지 표지 설치 ▶ 개구부 덮개 설치 및 위험표지 부착
A42: 1 | B42: 1. 토공사 | C42: 1.1 굴착 작업 | D42: 1.1.2 굴착 | E42: YES | F42: 개구부 | G42: 개구부(바닥개구부) | H42: 12대 기인물 | I42: 1 | J42: 0.09 | K42: 2016년 1월경 | L42: 42370 | M42: 1 | N42: 혹한기 | O42: 떨어짐 | P42: 2016년 1월경 OO공사에서 재해자가 하천 유입수가 고인 기초 굴착부 주변으로 설치해둔 로프에 위험표지를 부착하던 중 몸의 중심을 잃고 굴착부로 빠져 익사로 사망 | Q42: 기초 굴착부에 하천수 유입으로 생긴 물 웅덩이 주변으로 설치된 로프에 위험표지를 부착하던 중 동결된 토사에서 미끄러지면서 물웅덩이에 빠져 익사 | R42: ▶ 기초 굴착부에 PE드럼 및 로프를 설치하며 PE 드럼이 안전난간의 역할을 수행할 수 있게 안에 중량물(물, 모래, 흙 등)을 채움 ▶ 교각 기초굴착 단부에 근로자가 추락할 위험이 있는 경우 충분한 강도가 지닌 안전난간 등의 추락방지 조치 실시
A43: 1 | B43: 1. 토공사 | C43: 1.3 기초파일 작업 | D43: 1.3.2 기초파일 천공 | E43: YES | F43: 개구부 | G43: 개구부(기타개구부) | H43: 12대 기인물 | I43: 1 | J43: 0.09 | K43: 2019년 10월 | L43: 43739 | M43: 10 | N43: - | O43: 떨어짐 | P43: 2019년 10월경 재해자가 PRD(현장타설말뚝) 콘크리트 타설 후에 물청소용으로 사용할 물 호스를 뒷걸음(추정)으로 이동 시키던 중, 측량을 위하여 덮개를 열어 놓았던 개구부[PRD 천공 컷팅홀(□ 100x100Cm)]에 추락[지하2층 바닥(H≒9.95m)]하여 사망 | Q43: 콘크리트 말뚝 타설 후 물청소용으로 사용할 물 호스를 이동 중 측량을 위해 덮개를 열어놓은 개구부[PRD 천공 컷팅홀]에 추락 | R43: ▶ 추락 위험이 있는 장소에 방호조치를 가진 안전울(안전난간), 추락방망 등을 설치 및 개구부 표시 조치 ▶ 측량을 위해 개구부 덮개를 제거할 시 측량작업에 영향이 없는 안전울(안전난간)을 제작 및 설치
A44: 12 | B44: 12. 공통공사 | C44: 12.1 철거, 해체 | D44: 12.1.1 철거 및 해체 | E44: YES | F44: 개구부 | G44: 개구부(기타개구부) | H44: 12대 기인물 | I44: 1 | J44: 0.09 | K44: 2016년 12월 | L44: 42705 | M44: 12 | N44: 혹한기 | O44: 떨어짐 | P44: 2016년 12월경 OO증축공사 현장 지상4층(옥상)에서 철거공인 재해자가 폐기물 반출작업 중 몸의 중심을 잃고 슬래브 단부 약 10.7m아래 엘리베이터 피트 바닥에 추락하여 사망 | Q44: 엘레베이터 옥상 슬라브 단부에서 윈치를 이용하여 폐기물을 반출하기 위해 안전난간대 하부 개구부로 몸을 내밀어 윈치 인양고리 잡으려던 중 몸의 중심을 잃고 엘리베이터 피드 바닥으로 추락 | R44: ▶ 개구부 등 추락단부 안전난간대 설치 등 추락방호조치 실시 ▶ 불가피한 사유로 안전난간대 해체해야하는 경우 안전대부착설비 설치 및 안전대 체결 후 작업
A45: 12 | B45: 12. 공통공사 | C45: 12.1 철거, 해체 | D45: 12.1.1 철거 및 해체 | E45: YES | F45: 개구부 | G45: 개구부(기타개구부) | H45: 12대 기인물 | I45: 1 | J45: 0.09 | K45: 2018년 5월경 | L45: 43221 | M45: 5 | N45: - | O45: 떨어짐 | P45: 2018년 5월경 OO리모델링 현장 2층에서 재해자가 주방조적벽체 해체를 위해 주방발코니쪽에서 그라인더를 이용 벽체를 상단에서 하단으로 절단 중 그라인더날이 상단 조적벽체에 끼여 힘을 주어 빼내던중 기계와 함께 발코니 난간(H=70cm) 아래로(H=6m) 추락하여 사망 | Q45: 주방조적벽체 해체 작업 중 그라인더날이 조적벽체에 끼여 빼내던 중 기계와 함께 발코니 난간 아래로(70CM) 추락 | R45: ▶ 개구부 등 추락단부 안전난간대 설치 등 추락방호조치 실시 ▶ 근로자의 개인보호구, 안전대 체결여부 점검 및 관리감독
A46: 12 | B46: 12. 공통공사 | C46: 12.1 철거, 해체 | D46: 12.1.1 철거 및 해체 | E46: YES | F46: 개구부 | G46: 개구부(바닥개구부) | H46: 12대 기인물 | I46: 1 | J46: 0.09 | K46: 2018년 8월경 | L46: 43313 | M46: 8 | N46: 혹서기 | O46: 떨어짐 | P46: 2018년 8월경 OO철거공사 현장에서 재해자가 건물 옥상 바닥에 서서 상부 이동식크레인의 인양물(산소통 등 용단기구)을 신호하던 중 폐기물 투척구 겸 자재반입구(90cm x 120cm)에서 실족하여 지상 1층 바닥(H≒10m)으로 추락하여 사망 | Q46: 건축물 철거현장 옥상에서 이동식 크레인의 인양물 신호를 하던 중 실족하여 자재반입구를 통해 바닥으로 추락 | R46: ▶ 개구부 등 추락단부 안전난간대 설치 등 추락방호조치 실시 ▶ 근로자의 개인보호구, 안전대 체결여부 점검 및 관리감독
A47: 12 | B47: 12. 공통공사 | C47: 12.1 철거, 해체 | D47: 12.1.1 철거 및 해체 | E47: YES | F47: 개구부 | G47: 개구부(기타개구부) | H47: 12대 기인물 | I47: 1 | J47: 0.09 | K47: 2019년 4월경 | L47: 43556 | M47: 4 | N47: - | O47: 떨어짐 | P47: 2019년 4월경 OO철거 및 벽체 도장 공사를 위해 재해자가 동료작업자 2명과 함께 샌드위치 판넬 철거 작업 중에 의식을 잃고 바닥에 쓰러져 사망 | Q47: 지붕판넬 철거작업 중 경사면에 미끄러지면서 철거된 판넬 개구부를 통해 추락 | R47: ▶ 추락방호망, 안전대 부착설비 설치, 근로자의 안전대 체결 등 안전방호조치 실시 ▶ 근로자의 개인보호구, 안전대 체결여부 점검 및 관리감독
A48: 12 | B48: 12. 공통공사 | C48: 12.1 철거, 해체 | D48: 12.1.1 철거 및 해체 | E48: YES | F48: 개구부 | G48: 개구부(기타개구부) | H48: 12대 기인물 | I48: 1 | J48: 0.09 | K48: 2020년 5월경 | L48: 43952 | M48: 5 | N48: - | O48: 떨어짐 | P48: 2020년 5월경 OO(주) 공장건물 지붕에서 재해자가 지붕 판넬 철거작업을 위해 공장건물 지붕에서 판넬 고정나사를 제거 후 이동하던 중 판넬이 경사면을 따라 미끄러지면서 재해자가 판넬과 함께 공장 바닥(H≒3m)으로 추락하여 사망 | Q48: 지붕판넬 철거작업 중 경사면에 미끄러지면서 철거된 판넬 개구부를 통해 추락 | R48: ▶ 추락방호망, 안전대 부착설비 설치, 근로자의 안전대 체결 등 안전방호조치 실시 ▶ 근로자의 개인보호구, 안전대 체결여부 점검 및 관리감독
A49: 12 | B49: 12. 공통공사 | C49: 12.2 안전가시설 작업 | D49: 12.2.1 안전가시설(개구부) | E49: YES | F49: 개구부 | G49: 개구부(바닥개구부) | H49: 12대 기인물 | I49: 1 | J49: 0.09 | K49: 2017년 12월 | L49: 43070 | M49: 12 | N49: 혹한기 | O49: 떨어짐 | P49: 2017년 12월경 OO건설 토목공사현장에서 재해자 등 2명이 수로박스 내부 준공청소를 위해 수로박스 점검구 덮개(스틸 그레이팅)를 맨손으로 몸쪽으로 당기며 개방하던 중 걸침턱이 없던 좌측방향으로 전도되며 하부로 떨어질 때 동료작업자는 손을 놓았지만 재해자는 덮개와 함께 하부로 떨어져(H≒3m) 사망 | Q49: 수로박스 내부 준공청소를 위해 점검구 덮개를 맨손으로 당기며 개방하던 중 걸침턱이 없던 좌측방향으로 전도되며 하부로 떨어짐 | R49: ▶ 근로자 추락 위험이 있는 장소에 안전대 부착 설비 설치, 안전대 착용 등 추락방지 조치 실시 ▶ 스틸 그레이팅 덮개 개방시 근로자가 직접 하는 것이 아닌 이동식 크레인 등 인양장비를 이용하여 Belt Sling 등 사용
A50: 12 | B50: 12. 공통공사 | C50: 12.2 안전가시설 작업 | D50: 12.2.1 안전가시설(개구부) | E50: YES | F50: 개구부 | G50: 개구부(기타개구부) | H50: 12대 기인물 | I50: 1 | J50: 0.09 | K50: 2019년 4월경 | L50: 43556 | M50: 4 | N50: - | O50: 떨어짐 | P50: 2019년 4월경 OO공장 신축공사 현장에서 재해자는 건물내부 청소작업 중 발생되는 쓰레기를 반출하고자 카리프트 겸용 화물용승강기 운반구에 싣던 중 벽체와 일부 개방된 화물용 승강기 운반구 도어의 수직 개구부를 통해 아래(약 H=22m)로 추락 | Q50: 자재 운반 및 작업 중 안전난간이 미설치된 창호 개구부 등을 통해 근로자 추락 | R50: ▶ 창호 개구부 등 추락의 위험이 있는 장소에는 안전난간대 설치 또는 수직형 추락방망 등 추락방지용 안전시설물을 설치하여 근로자 추락을 예방 ▶ 설치된 안전시설물에 대해 유지관리하고, 임의 해체 예방을 위한 관리감독
A51: 12 | B51: 12. 공통공사 | C51: 12.2 안전가시설 작업 | D51: 12.2.1 안전가시설(개구부) | E51: YES | F51: 개구부 | G51: 개구부(바닥개구부) | H51: 12대 기인물 | I51: 1 | J51: 0.09 | K51: 2019년 8월경 | L51: 43678 | M51: 8 | N51: 혹서기 | O51: 떨어짐 | P51: 2019년 8월경 지하주차장 청소작업을 하던 재해자가 폐쇄형 점검구 내부에서 몸의 중심을 잃고, 점검구 내 개구부(△2.3x2.4x3.2m) 약 5m 아래 콘크리트 바닥으로 떨어져 사망 | Q51: 덮개가 고정되지 않은 개구부 인근에서 작업 중 바닥으로 추락함 | R51: ▶ 추락을 방지하기 위한 안전대 체결 ▶ 개구부 덮개 설치 및 위험표지 부착
A52: 12 | B52: 12. 공통공사 | C52: 12.2 안전가시설 작업 | D52: 12.2.1 안전가시설(개구부) | E52: YES | F52: 개구부 | G52: 개구부(바닥개구부) | H52: 12대 기인물 | I52: 1 | J52: 0.09 | K52: 2020년 2월경 | L52: 43862 | M52: 2 | N52: 혹한기 | O52: 떨어짐 | P52: 2020년 2월경 OO건설 공사현장에서 청소 작업을 하던 작업자가 지하1층 바닥 개구부(1.2mX0.7m)에서 지하2층 저수조 바닥으로 추락(H=5.0m)하여 사망 | Q52: 덮개가 고정되지 않은 개구부 인근에서 작업 중 바닥으로 추락함 | R52: ▶ 방지하기 위한 안전대 착용 ▶ 개구부 덮개 설치 및 위험표지 부착
... A90: 2 | B90: 2. 철근콘크리트공사 | C90: 2.1 거푸집 작업 | D90: 2.1.3 거푸집 동바리 해체 | E90: YES | F90: 개구부 | G90: 개구부(바닥개구부) | H90: 12대 기인물 | I90: 1 | J90: 0.09 | K90: 2018년 11월 | L90: 43405 | M90: 11 | N90: - | O90: 떨어짐 | P90: 2018년 11월경 OO건설(주) OO신축공사 현장 지하6층에서 협력업체 소속 재해자가 벽/기둥 형틀 해체 구간의 떨어진 콘크리트 잔재물을 슬리브덮개를 밟고 청소작업 중 지하 7층 바닥(높이 약 6.3m)으로 추락하여 사망 | Q90: 개구부 방호조치 미흡한 상태에서 벽/기둥 형틀 해체 구간의 떨어진 콘크리트 잔재물을 슬리브덮개를 밟고 청소작업 중, 근로자 추락 | R90: ▶ 견고한 개구부 덮개 설치 및 개구부 위험표지 부착 ▶ 이동식 조명 사용을 통한 적정 조도 확보 ▶ 작업방법/안전 교육 실시 및 관리감독 철저
A91: 2 | B91: 2. 철근콘크리트공사 | C91: 2.3 철근 작업 | D91: 2.3.2 철근 가공 및 운반 | E91: YES | F91: 개구부 | G91: 개구부(바닥개구부) | H91: 12대 기인물 | I91: 1 | J91: 0.09 | K91: 도시시설물공사 현 | L91: X | M91: #VALUE! | N91: #VALUE! | O91: 떨어짐 | P91: 도시시설물공사 현장에서 교량 Girder상부에 적치된 각파이프 묶음(무게≒600kg)의 벤딩 절단작업 중 각파이프가 전도되어 작업발판 상부에 낙하하면서 그 충격에 의해 작업발판 2개가 탈락하였고, 뚫린 개구부(0.8m×1.8m)를 통해 재해자가 토사 바닥으로 추락(H≒5m)하여 사망 | Q91: 적재된 자재가 넘어지며 작업발판이 탈락되어 주변 근로자 추락 | R91: ▶ 철근 등 중량물 적재 시 붕괴의 우려가 없는 받침판 위에 적재 또는 최대 적재하중을 초과하지 않는 선에서의 적재 ▶ 추락방지조치를 위한 안전대 부착설비 설치 및 안전대 착용
A92: 2 | B92: 2. 철근콘크리트공사 | C92: 2.3 철근 작업 | D92: 2.3.3 철근 조립 | E92: YES | F92: 개구부 | G92: 개구부(바닥개구부) | H92: 12대 기인물 | I92: 1 | J92: 0.09 | K92: 2016년 7월경 | L92: 42552 | M92: 7 | N92: 혹서기 | O92: 떨어짐 | P92: 2016년 7월경 OO(주) OO프라자 신축공사 현장에서 재해자가 지상4층 보 철근 조립 중에 주변 바닥 개구부(자재 반입구)로 떨어져(H≒16.2m) 사망 | Q92: 보 철근 조립 중, 안전난간 미설치된 주변 바닥 개구부를 통해 중심을 잃고 근로자 추락 | R92: ▶ 자재 반입구와 같이 개구부로서 떨어질 위험이 있는 경우 안전난간 또는 안전방망과 같이 추락방호시설 설치 ▶ 안전난간 또는 안전방망 설치가 곤란한 경우 안전대 지급 및 안전대를 걸 수 있는 안전대 부착설비 설치
A93: 2 | B93: 2. 철근콘크리트공사 | C93: 2.4 콘크리트 작업 | D93: 2.4.1 콘크리트 반입, 운반 | E93: YES | F93: 개구부 | G93: 개구부(기타개구부) | H93: 12대 기인물 | I93: 1 | J93: 0.09 | K93: 2016년 12월 | L93: 42705 | M93: 12 | N93: 혹한기 | O93: 떨어짐 | P93: 2016년 12월경 OO노반건설공사 환기구에서 터널 라이닝 타설에 필요한 콘크리트를 실은 레미콘 차량을 카리프트에 탑승시킨 후에 재해자는 옆에 별도로 위치한 리프트에 탑승 후 상부로 이동하여 대기 중 레미콘 차량을 탑승시킨 카리프트가 상승 중에 레미콘 차량의 사이드 브레이크 미잠금(추정) 상태로 상부 이동 중 카리프트 구간별 속도 변화 등으로 인하여 차량이 전면부로 미끄러져 쏠리면서 지상 1.5m 아래에 있는 지상 복공판 H-beam 사이에 차량 전면부가 끼어 찌그러져 있는 상태에서 재해자가 차량 고임목 설치 및 본인의 휴대폰을 가지러 출입금지 구역인 카리프트 내부로 들어가 후방 타이어 오른쪽 부위에 각재 고임목을 대고, 레미콘차량 전면부 깨진 유리창을 통하여 차를 딛고 운전석으로 올라가다가 차에서 미끄러져 차와 카리프트 사이에 50cm*50cm의 개구부로 추락, 61m 아래 터널 콘크리트 바닥으로 추락하여 사망 | Q93: 카리프트 내부에서 레미콘 차량이 전면부로 미끄러져 전면부 파손 이후 근로자가 본인의 물품을 챙기러 파손된 전면부 유리창을 통하여 차를 딛고 운전석으로 올라가던 중 미끄러져 차와 카리프트 사이 개구부로 추락 | R93: ▶ 개구부 등 낙하 위험이 있는 장소에는 방책 등 설치하여 출입 금지 및 표지판 설치 ▶ 카리프트 등 양중기 사용 시 레미콘차량 등이 완전히 빠져나갈 때 까지 모니터 주시
...

Sheet Dashboard 입력
A1: JSA 위험성평가 양식
A2: 관리번호 | B2: RA-2025-0315 | I2: 이 프로그램을 웹으로 배포 하는건 어때? PDF 출력하면 훨 편해, 그리고 근로자에게 주지할 사항도 자동으로 주는거지
A3: 작업 명 | B3: 전기설비 점검 및 정비작업
A4: 작업내용 | B4: 전기실 내 배전반 교체 및 케이블 정비, 접지 점검 | AL4: 고위험공정 자동 지정
I5: 자동 체크 | O5: 자동반영 | AB5: 위험성평가 데이터 입력 | AL5: 📊 위험성평가 데이터 분석 대시보드 (자동 연동)
A6: 고위험 기인물 해당여부 체크 | H6: 작업분류 | M6: 이부분도 연동하자 | O6: ① 작업개요 입력 (저장 후 Table 1에 연동) | U6: 공정 내용 | X6: 기인물 적용 공정 및 작업내용 입력 | AB6: ② 위험성평가 데이터 입력 (저장 후 Table 2에 연동) - 행 추가로 공정 확장 | AL6: ① 공정별 위험성 분석 (자동 연동 · 최대 50공정) | AT6: ② 위험성 등급 분포 (자동 연동)
A7: No. | B7: 기인물 | C7: 사망건수 | D7: 체크 | E7: 중장비여부 | F7: 고소, 감전 | H7: 순 | I7: 구분 | J7: 결과 | K7: 수동 | L7: 자동 | M7: 비고 | O7: 항목 | P7: 입력란 | Q7: 항목 | R7: 출력부 | S7: 직접입력 | U7: 관리번호 | V7: 작업단계 (공정) | W7: 작업내용 | X7: 기인물 | Z7: SIF 지정 기인물 목록 | AB7: 공정번호 | AC7: 작업(공정)단계 | AD7: 유해위험요인 | AE7: 안전조치사항 | AF7: 가능성(전) | AG7: 중대성(전) | AH7: 위험도(전) | AI7: 가능성 (빈도) | AJ7: 중대성 (강도) | AK7: 위험성 | AL7: 작업공정 | AM7: 위험요인 수 | AN7: 고위험 건수 (위험도≥9) | AO7: 평균위험도 (개선전) | AP7: 평균위험도 (개선후) | AQ7: 위험도 감소율 | AR7: 위험성 분류 | AT7: 위험성 등급 | AU7: 기준 (위험도) | AV7: 개선전 건수 | AW7: 개선후 건수 | AX7: 변화
A8: 1 | B8: 지붕(처마,홈통) | C8: 129 | D8: 해당 | F8: 고소 | H8: 1 | I8: 일반작업 | J8: =IF(OR(K8="해당",L8="해당"),"해당","미해당") -> 해당 | K8: 해당 | O8: 통제번호 (=관리번호) | P8: =B2 -> RA-2025-0315 | Q8: 회사(부서)명 | R8: =S8 -> 한국에너지 전기부 | S8: 한국에너지 전기부 | U8: 1 | V8: 전원차단 | Z8: {=_xlfn._xlws.FILTER(B8:B65,D8:D65="해당","")} -> 지붕(처마,홈통) | AB8: 1-1 | AC8: 전원차단 | AD8: 차단기 오조작으로 감전 | AE8: LOTO 절차 준수, 검전기 확인 | AF8: 2 | AG8: 5 | AH8: =IF(AND(AF8<>"",AG8<>""),AF8*AG8,"") -> 10 | AI8: 2 | AJ8: 1 | AK8: =IF(AND(AI8<>"",AJ8<>""),AI8*AJ8,"") -> 2 | AL8: {=IFERROR(INDEX(_xlfn._xlws.SORT(_xlfn.UNIQUE(_xlfn._xlws.FILTER(AC$8:AC$307,AC$8:AC$307<>""))),1),"")} -> ㄱㄱㄱ | AM8: =IF(AL8="","",COUNTIF(AC$8:AC$307,AL8)) -> 1 | AN8: =IF(AL8="","",COUNTIFS(AC$8:AC$307,AL8,AH$8:AH$307,">="&9)) -> 0 | AO8: =IF(AL8="","",IFERROR(ROUND(AVERAGEIFS(AH$8:AH$307,AC$8:AC$307,AL8,AH$8:AH$307,"<>"),1),"-")) -> 4 | AP8: =IF(AL8="","",IFERROR(ROUND(AVERAGEIFS(AK$8:AK$307,AC$8:AC$307,AL8,AK$8:AK$307,"<>"),1),"-")) -> - | AQ8: =IF(OR(AL8="",AO8="-",AP8="-"),"",IF(AO8=0,0,(AO8-AP8)/AO8)) | AR8: =IF(AL8="","",IF(AO8="-","미입력",IF(AP8="-",IF(AO8>=9,"고위험⚠",IF(AO8>=6,"중위험⚠","저위험⚠")),IF(AO8>=9,"고위험",IF(AO8>=6,"중위험","저위험"))))) -> 저위험⚠ | AT8: 매우위험(VH) | AU8: ≥13 | AV8: =COUNTIF(AH$8:AH$307,">="&13) -> 6 | AW8: =COUNTIF(AK$8:AK$307,">="&13) -> 0 | AX8: =AW8-AV8 -> -6
A9: 2 | B9: 비계 | C9: 129 | D9: 미해당 | F9: 고소 | H9: 2 | I9: 화기작업 | J9: =IF(OR(K9="해당",L9="해당"),"해당","미해당") -> 미해당 | M9: 화기감시자 배치 필 | O9: 작업 명 | P9: =B3 -> 전기설비 점검 및 정비작업 | Q9: 작성일자 | R9: =S9 -> 2025.03.14 | S9: 2025.03.14 | U9: 2 | V9: 배전반 해체 | Z9: 사다리 | AB9: 1-2 | AC9: 전원차단 | AD9: 아크플래시 발생 | AE9: 절연장갑 착용, 안면보호구 | AF9: 2 | AG9: 4 | AH9: =IF(AND(AF9<>"",AG9<>""),AF9*AG9,"") -> 8 | AI9: 1 | AJ9: 3 | AK9: =IF(AND(AI9<>"",AJ9<>""),AI9*AJ9,"") -> 3 | AL9: {=IFERROR(INDEX(_xlfn._xlws.SORT(_xlfn.UNIQUE(_xlfn._xlws.FILTER(AC$8:AC$307,AC$8:AC$307<>""))),2),"")} -> ㄴㅇ | AM9: =IF(AL9="","",COUNTIF(AC$8:AC$307,AL9)) -> 3 | AN9: =IF(AL9="","",COUNTIFS(AC$8:AC$307,AL9,AH$8:AH$307,">="&9)) -> 2 | AO9: =IF(AL9="","",IFERROR(ROUND(AVERAGEIFS(AH$8:AH$307,AC$8:AC$307,AL9,AH$8:AH$307,"<>"),1),"-")) -> 7.3 | AP9: =IF(AL9="","",IFERROR(ROUND(AVERAGEIFS(AK$8:AK$307,AC$8:AC$307,AL9,AK$8:AK$307,"<>"),1),"-")) -> - | AQ9: =IF(OR(AL9="",AO9="-",AP9="-"),"",IF(AO9=0,0,(AO9-AP9)/AO9)) | AR9: =IF(AL9="","",IF(AO9="-","미입력",IF(AP9="-",IF(AO9>=9,"고위험⚠",IF(AO9>=6,"중위험⚠","저위험⚠")),IF(AO9>=9,"고위험",IF(AO9>=6,"중위험","저위험"))))) -> 중위험⚠ | AT9: 고위험(H) | AU9: 9~12 | AV9: =COUNTIFS(AH$8:AH$307,">="&9,AH$8:AH$307,"<"&13) -> 19 | AW9: =COUNTIFS(AK$8:AK$307,">="&9,AK$8:AK$307,"<"&13) -> 0 | AX9: =AW9-AV9 -> -19
A10: 3 | B10: 철골(철골구조물) | C10: 118 | D10: 미해당 | F10: 고소 | H10: 3 | I10: 밀폐작업 | J10: =IF(OR(K10="해당",L10="해당"),"해당","미해당") -> 미해당 | M10: 산소농도측정 필 | O10: 작업내용 | P10: =B4 -> 전기실 내 배전반 교체 및 케이블 정비, 접지 점검 | Q10: 작성자 | R10: =S10 -> 김안전, 이이경 | S10: 김안전, 이이경 | U10: 3 | V10: 케이블 정비 | Z10: 굴착기 | AB10: 1-3 | AC10: 전원차단 | AD10: 잔류전압에 의한 감전 | AE10: 콘덴서 방전 후 작업 시작 | AF10: 3 | AG10: 5 | AH10: =IF(AND(AF10<>"",AG10<>""),AF10*AG10,"") -> 15 | AI10: 2 | AJ10: 1 | AK10: =IF(AND(AI10<>"",AJ10<>""),AI10*AJ10,"") -> 2 | AL10: {=IFERROR(INDEX(_xlfn._xlws.SORT(_xlfn.UNIQUE(_xlfn._xlws.FILTER(AC$8:AC$307,AC$8:AC$307<>""))),3),"")} -> ㄹㄹㅇ | AM10: =IF(AL10="","",COUNTIF(AC$8:AC$307,AL10)) -> 1 | AN10: =IF(AL10="","",COUNTIFS(AC$8:AC$307,AL10,AH$8:AH$307,">="&9)) -> 0 | AO10: =IF(AL10="","",IFERROR(ROUND(AVERAGEIFS(AH$8:AH$307,AC$8:AC$307,AL10,AH$8:AH$307,"<>"),1),"-")) -> 4 | AP10: =IF(AL10="","",IFERROR(ROUND(AVERAGEIFS(AK$8:AK$307,AC$8:AC$307,AL10,AK$8:AK$307,"<>"),1),"-")) -> - | AQ10: =IF(OR(AL10="",AO10="-",AP10="-"),"",IF(AO10=0,0,(AO10-AP10)/AO10)) | AR10: =IF(AL10="","",IF(AO10="-","미입력",IF(AP10="-",IF(AO10>=9,"고위험⚠",IF(AO10>=6,"중위험⚠","저위험⚠")),IF(AO10>=9,"고위험",IF(AO10>=6,"중위험","저위험"))))) -> 저위험⚠ | AT10: 중위험(M) | AU10: 4~8 | AV10: =COUNTIFS(AH$8:AH$307,">="&4,AH$8:AH$307,"<"&9) -> 21 | AW10: =COUNTIFS(AK$8:AK$307,">="&4,AK$8:AK$307,"<"&9) -> 0 | AX10: =AW10-AV10 -> -21
A11: 4 | B11: 사다리 | C11: 116 | D11: 해당 | F11: 고소 | H11: 4 | I11: 고소작업 | J11: =IF(OR(K11="해당",L11="해당"),"해당","미해당") -> 해당 | L11: {=IF(SUMPRODUCT(($F$8:$F$65="고소")*($D$8:$D$65="해당"))>=1,"해당","미해당")} -> 해당 | O11: 작업기간(시간) | P11: 2025.03.15 09:00 ~ 18:00 | Q11: 평가 참여자 | R11: =IF(COUNTA(J21:J50)<=5, _xlfn.TEXTJOIN(", ",TRUE,J21:J50), _xlfn.TEXTJOIN(", ",TRUE,J21:J25)&" 등 총 "&COUNTA(J21:J50)&"명") -> 김가나1, 김가나2, 김가나3, 김가나4, 김가나5 등 총 23명 | U11: 4 | V11: 접지 점검 | Z11: 개구부(바닥개구부) | AB11: 2-1 | AC11: 배전반 해체 | AD11: 볼트 풀림 시 날카로운 모서리에 절상 | AE11: 절연장갑 및 안전장갑 착용 | AF11: 3 | AG11: 2 | AH11: =IF(AND(AF11<>"",AG11<>""),AF11*AG11,"") -> 6 | AI11: 1 | AJ11: 3 | AK11: =IF(AND(AI11<>"",AJ11<>""),AI11*AJ11,"") -> 3 | AL11: {=IFERROR(INDEX(_xlfn._xlws.SORT(_xlfn.UNIQUE(_xlfn._xlws.FILTER(AC$8:AC$307,AC$8:AC$307<>""))),4),"")} -> ㅁㅁ | AM11: =IF(AL11="","",COUNTIF(AC$8:AC$307,AL11)) -> 1 | AN11: =IF(AL11="","",COUNTIFS(AC$8:AC$307,AL11,AH$8:AH$307,">="&9)) -> 1 | AO11: =IF(AL11="","",IFERROR(ROUND(AVERAGEIFS(AH$8:AH$307,AC$8:AC$307,AL11,AH$8:AH$307,"<>"),1),"-")) -> 9 | AP11: =IF(AL11="","",IFERROR(ROUND(AVERAGEIFS(AK$8:AK$307,AC$8:AC$307,AL11,AK$8:AK$307,"<>"),1),"-")) -> - | AQ11: =IF(OR(AL11="",AO11="-",AP11="-"),"",IF(AO11=0,0,(AO11-AP11)/AO11)) | AR11: =IF(AL11="","",IF(AO11="-","미입력",IF(AP11="-",IF(AO11>=9,"고위험⚠",IF(AO11>=6,"중위험⚠","저위험⚠")),IF(AO11>=9,"고위험",IF(AO11>=6,"중위험","저위험"))))) -> 고위험⚠ | AT11: 저위험(L) | AU11: 1~3 | AV11: =COUNTIFS(AH$8:AH$307,">="&1,AH$8:AH$307,"<"&4) -> 0 | AW11: =COUNTIFS(AK$8:AK$307,">="&1,AK$8:AK$307,"<"&4) -> 40 | AX11: =AW11-AV11 -> 40
A12: 5 | B12: 고소작업대 | C12: 114 | D12: 미해당 | E12: 중장비 | F12: 고소 | H12: 5 | I12: 정전작업 | J12: =IF(OR(K12="해당",L12="해당"),"해당","미해당") -> 미해당 | K12: 미해당 | L12: {=IF(SUMPRODUCT(($F$8:$F$65="감전")*($D$8:$D$65="해당"))>=1,"해당","미해당")} -> 미해당 | O12: 작업장소 | P12: A동 전기실, B동 전기실 | Q12: 필요한 보호구 | R12: =S12 -> 절연장갑, 절연장화, 안전모, 보안경 | S12: 절연장갑, 절연장화, 안전모, 보안경 | U12: 5 | V12: 새 배전반 설치 | Z12: 기계설비 | AB12: 2-2 | AC12: 배전반 해체 | AD12: 배전반 넘어짐으로 충돌 | AE12: 작업반경 정리정돈, 바닥 전선 정리 | AF12: 2 | AG12: 3 | AH12: =IF(AND(AF12<>"",AG12<>""),AF12*AG12,"") -> 6 | AI12: 2 | AJ12: 1 | AK12: =IF(AND(AI12<>"",AJ12<>""),AI12*AJ12,"") -> 2 | AL12: {=IFERROR(INDEX(_xlfn._xlws.SORT(_xlfn.UNIQUE(_xlfn._xlws.FILTER(AC$8:AC$307,AC$8:AC$307<>""))),5),"")} -> 배전반 해체 | AM12: =IF(AL12="","",COUNTIF(AC$8:AC$307,AL12)) -> 6 | AN12: =IF(AL12="","",COUNTIFS(AC$8:AC$307,AL12,AH$8:AH$307,">="&9)) -> 0 | AO12: =IF(AL12="","",IFERROR(ROUND(AVERAGEIFS(AH$8:AH$307,AC$8:AC$307,AL12,AH$8:AH$307,"<>"),1),"-")) -> 6 | AP12: =IF(AL12="","",IFERROR(ROUND(AVERAGEIFS(AK$8:AK$307,AC$8:AC$307,AL12,AK$8:AK$307,"<>"),1),"-")) -> 2.7 | AQ12: =IF(OR(AL12="",AO12="-",AP12="-"),"",IF(AO12=0,0,(AO12-AP12)/AO12)) -> 0.55 | AR12: =IF(AL12="","",IF(AO12="-","미입력",IF(AP12="-",IF(AO12>=9,"고위험⚠",IF(AO12>=6,"중위험⚠","저위험⚠")),IF(AO12>=9,"고위험",IF(AO12>=6,"중위험","저위험"))))) -> 중위험 | AT12: 합계 | AV12: =SUM(AV8:AV11) -> 46 | AW12: =SUM(AW8:AW11) -> 40 | AX12: =SUM(AX8:AX11) -> -6
A13: 6 | B13: 굴착기 | C13: 104 | D13: 해당 | E13: 굴착 | H13: 6 | I13: 굴착작업 | J13: =IF(OR(K13="해당",L13="해당"),"해당","미해당") -> 해당 | K13: 미해당 | L13: {=IF(SUMPRODUCT(($E$8:$E$65="굴착")*($D$8:$D$65="해당"))>=1,"해당","미해당")} -> 해당 | M13: 중장비 작업계획서, 신호수 필 | O13: 작업분류 | P13: {=_xlfn.TEXTJOIN(" ", TRUE, IF(J8:J17="해당", "■ "&I8:I17, ""))} -> ■ 일반작업 ■ 고소작업 ■ 굴착작업 ■ 중장비작업 | Q13: 투입 중장비 | R13: {=_xlfn.TEXTJOIN(", ",TRUE,IF((D8:D65="해당")*(E8:E65="중장비"),B8:B65,""))&IF(S13<>"",", "&S13,"")} -> 이동식크레인, 기타건설장비, 천공기/항타기, 리프트, 지게차 | U13: 6 | V13: 케이블 결선 | Z13: 이동식비계 | AB13: 2-3 | AC13: 배전반 해체 | AD13: 부품 낙하로 인한 부상 | AE13: 헬멧 착용, 낙하방지망 설치 | AF13: 2 | AG13: 3 | AH13: =IF(AND(AF13<>"",AG13<>""),AF13*AG13,"") -> 6 | AI13: 1 | AJ13: 3 | AK13: =IF(AND(AI13<>"",AJ13<>""),AI13*AJ13,"") -> 3 | AL13: {=IFERROR(INDEX(_xlfn._xlws.SORT(_xlfn.UNIQUE(_xlfn._xlws.FILTER(AC$8:AC$307,AC$8:AC$307<>""))),6),"")} -> 새 배전반 설치 | AM13: =IF(AL13="","",COUNTIF(AC$8:AC$307,AL13)) -> 6 | AN13: =IF(AL13="","",COUNTIFS(AC$8:AC$307,AL13,AH$8:AH$307,">="&9)) -> 2 | AO13: =IF(AL13="","",IFERROR(ROUND(AVERAGEIFS(AH$8:AH$307,AC$8:AC$307,AL13,AH$8:AH$307,"<>"),1),"-")) -> 7 | AP13: =IF(AL13="","",IFERROR(ROUND(AVERAGEIFS(AK$8:AK$307,AC$8:AC$307,AL13,AK$8:AK$307,"<>"),1),"-")) -> 2.3 | AQ13: =IF(OR(AL13="",AO13="-",AP13="-"),"",IF(AO13=0,0,(AO13-AP13)/AO13)) -> 0.67142857 | AR13: =IF(AL13="","",IF(AO13="-","미입력",IF(AP13="-",IF(AO13>=9,"고위험⚠",IF(AO13>=6,"중위험⚠","저위험⚠")),IF(AO13>=9,"고위험",IF(AO13>=6,"중위험","저위험"))))) -> 중위험
A14: 7 | B14: 슬라브단부 | C14: 92 | D14: 미해당 | F14: 고소 | H14: 7 | I14: 중장비작업 | J14: =IF(OR(K14="해당",L14="해당"),"해당","미해당") -> 해당 | L14: {=IF(SUMPRODUCT(($E$8:$E$65="중장비")*($D$8:$D$65="해당"))>=1,"해당","미해당")} -> 해당 | M14: 중장비작업계획서, 신호수 교육 | O14: 중점관리사항 | P14: 감전위험, 아크플래시, 케이블 노후 | Q14: 필요한 공기구 | R14: =S14 -> 스카이 등 | S14: 스카이 등 | U14: 7 | V14: 시운전 및 점검 | Z14: 토사 | AB14: 3-1 | AC14: 케이블 정비 | AD14: 피복손상으로 감전 | AE14: 절연저항 측정 후 작업 | AF14: 3 | AG14: 4 | AH14: =IF(AND(AF14<>"",AG14<>""),AF14*AG14,"") -> 12 | AI14: 2 | AJ14: 1 | AK14: =IF(AND(AI14<>"",AJ14<>""),AI14*AJ14,"") -> 2 | AL14: {=IFERROR(INDEX(_xlfn._xlws.SORT(_xlfn.UNIQUE(_xlfn._xlws.FILTER(AC$8:AC$307,AC$8:AC$307<>""))),7),"")} -> 시운전 및 점검 | AM14: =IF(AL14="","",COUNTIF(AC$8:AC$307,AL14)) -> 4 | AN14: =IF(AL14="","",COUNTIFS(AC$8:AC$307,AL14,AH$8:AH$307,">="&9)) -> 4 | AO14: =IF(AL14="","",IFERROR(ROUND(AVERAGEIFS(AH$8:AH$307,AC$8:AC$307,AL14,AH$8:AH$307,"<>"),1),"-")) -> 12.5 | AP14: =IF(AL14="","",IFERROR(ROUND(AVERAGEIFS(AK$8:AK$307,AC$8:AC$307,AL14,AK$8:AK$307,"<>"),1),"-")) -> 2 | AQ14: =IF(OR(AL14="",AO14="-",AP14="-"),"",IF(AO14=0,0,(AO14-AP14)/AO14)) -> 0.84 | AR14: =IF(AL14="","",IF(AO14="-","미입력",IF(AP14="-",IF(AO14>=9,"고위험⚠",IF(AO14>=6,"중위험⚠","저위험⚠")),IF(AO14>=9,"고위험",IF(AO14>=6,"중위험","저위험"))))) -> 고위험
A15: 8 | B15: 지붕(채광판,선라이트) | C15: 90 | D15: 미해당 | F15: 고소 | H15: 8 | I15: 중량물작업 | J15: =IF(OR(K15="해당",L15="해당"),"해당","미해당") -> 미해당 | M15: 중량물작업계획서 | O15: 작업절차서 | Z15: 기타자재(내부마감재,시멘트,마대) | AB15: 3-2 | AC15: 케이블 정비 | AD15: 케이블 단선 처리 시 천공 | AE15: 단선 케이블 처리함 사용, 분리 보관 | AF15: 2 | AG15: 2 | AH15: =IF(AND(AF15<>"",AG15<>""),AF15*AG15,"") -> 4 | AI15: 1 | AJ15: 3 | AK15: =IF(AND(AI15<>"",AJ15<>""),AI15*AJ15,"") -> 3 | AL15: {=IFERROR(INDEX(_xlfn._xlws.SORT(_xlfn.UNIQUE(_xlfn._xlws.FILTER(AC$8:AC$307,AC$8:AC$307<>""))),8),"")} -> 전원차단 | AM15: =IF(AL15="","",COUNTIF(AC$8:AC$307,AL15)) -> 6 | AN15: =IF(AL15="","",COUNTIFS(AC$8:AC$307,AL15,AH$8:AH$307,">="&9)) -> 4 | AO15: =IF(AL15="","",IFERROR(ROUND(AVERAGEIFS(AH$8:AH$307,AC$8:AC$307,AL15,AH$8:AH$307,"<>"),1),"-")) -> 11 | AP15: =IF(AL15="","",IFERROR(ROUND(AVERAGEIFS(AK$8:AK$307,AC$8:AC$307,AL15,AK$8:AK$307,"<>"),1),"-")) -> 2.3 | AQ15: =IF(OR(AL15="",AO15="-",AP15="-"),"",IF(AO15=0,0,(AO15-AP15)/AO15)) -> 0.79090909 | AR15: =IF(AL15="","",IF(AO15="-","미입력",IF(AP15="-",IF(AO15>=9,"고위험⚠",IF(AO15>=6,"중위험⚠","저위험⚠")),IF(AO15>=9,"고위험",IF(AO15>=6,"중위험","저위험"))))) -> 고위험
A16: 9 | B16: 작업발판/가설계단 | C16: 85 | D16: 미해당 | F16: 고소 | H16: 9 | I16: 방사선작업 | J16: =IF(OR(K16="해당",L16="해당"),"해당","미해당") -> 미해당 | O16: ✔ 저장 후 이 보호구명등을 일괄 DB에 기록한다 | Z16: 이동식크레인 | AB16: 3-3 | AC16: 케이블 정비 | AD16: 케이블 트레이 날카로운 부분에 절상 | AE16: 안전장갑 착용, 날카로운 부분 테이핑 | AF16: 3 | AG16: 2 | AH16: =IF(AND(AF16<>"",AG16<>""),AF16*AG16,"") -> 6 | AI16: 2 | AJ16: 1 | AK16: =IF(AND(AI16<>"",AJ16<>""),AI16*AJ16,"") -> 2 | AL16: {=IFERROR(INDEX(_xlfn._xlws.SORT(_xlfn.UNIQUE(_xlfn._xlws.FILTER(AC$8:AC$307,AC$8:AC$307<>""))),9),"")} -> 접지 점검 | AM16: =IF(AL16="","",COUNTIF(AC$8:AC$307,AL16)) -> 6 | AN16: =IF(AL16="","",COUNTIFS(AC$8:AC$307,AL16,AH$8:AH$307,">="&9)) -> 4 | AO16: =IF(AL16="","",IFERROR(ROUND(AVERAGEIFS(AH$8:AH$307,AC$8:AC$307,AL16,AH$8:AH$307,"<>"),1),"-")) -> 10.3 | AP16: =IF(AL16="","",IFERROR(ROUND(AVERAGEIFS(AK$8:AK$307,AC$8:AC$307,AL16,AK$8:AK$307,"<>"),1),"-")) -> 2.7 | AQ16: =IF(OR(AL16="",AO16="-",AP16="-"),"",IF(AO16=0,0,(AO16-AP16)/AO16)) -> 0.73786408 | AR16: =IF(AL16="","",IF(AO16="-","미입력",IF(AP16="-",IF(AO16>=9,"고위험⚠",IF(AO16>=6,"중위험⚠","저위험⚠")),IF(AO16>=9,"고위험",IF(AO16>=6,"중위험","저위험"))))) -> 고위험
A17: 10 | B17: 개구부(바닥개구부) | C17: 80 | D17: 해당 | F17: 고소 | H17: 10 | I17: 잠수작업 | J17: =IF(OR(K17="해당",L17="해당"),"해당","미해당") -> 미해당 | Z17: 철골(철골자재) | AB17: 4-1 | AC17: 접지 점검 | AD17: 접지저항 미확보로 감전 위험 | AE17: 접지측정기로 저항값 확인 후 작업 | AF17: 3 | AG17: 5 | AH17: =IF(AND(AF17<>"",AG17<>""),AF17*AG17,"") -> 15 | AI17: 1 | AJ17: 3 | AK17: =IF(AND(AI17<>"",AJ17<>""),AI17*AJ17,"") -> 3 | AL17: {=IFERROR(INDEX(_xlfn._xlws.SORT(_xlfn.UNIQUE(_xlfn._xlws.FILTER(AC$8:AC$307,AC$8:AC$307<>""))),10),"")} -> 케이블 결선 | AM17: =IF(AL17="","",COUNTIF(AC$8:AC$307,AL17)) -> 6 | AN17: =IF(AL17="","",COUNTIFS(AC$8:AC$307,AL17,AH$8:AH$307,">="&9)) -> 6 | AO17: =IF(AL17="","",IFERROR(ROUND(AVERAGEIFS(AH$8:AH$307,AC$8:AC$307,AL17,AH$8:AH$307,"<>"),1),"-")) -> 10.7 | AP17: =IF(AL17="","",IFERROR(ROUND(AVERAGEIFS(AK$8:AK$307,AC$8:AC$307,AL17,AK$8:AK$307,"<>"),1),"-")) -> 2.7 | AQ17: =IF(OR(AL17="",AO17="-",AP17="-"),"",IF(AO17=0,0,(AO17-AP17)/AO17)) -> 0.74766355 | AR17: =IF(AL17="","",IF(AO17="-","미입력",IF(AP17="-",IF(AO17>=9,"고위험⚠",IF(AO17>=6,"중위험⚠","저위험⚠")),IF(AO17>=9,"고위험",IF(AO17>=6,"중위험","저위험"))))) -> 고위험
A18: 11 | B18: 거푸집 | C18: 80 | D18: 미해당 | Z18: 벽체 | AB18: 4-2 | AC18: 접지 점검 | AD18: 접지선 풀림으로 감전 | AE18: 접지선 체결 상태 사전 확인 | AF18: 2 | AG18: 5 | AH18: =IF(AND(AF18<>"",AG18<>""),AF18*AG18,"") -> 10 | AI18: 2 | AJ18: 1 | AK18: =IF(AND(AI18<>"",AJ18<>""),AI18*AJ18,"") -> 2 | AL18: {=IFERROR(INDEX(_xlfn._xlws.SORT(_xlfn.UNIQUE(_xlfn._xlws.FILTER(AC$8:AC$307,AC$8:AC$307<>""))),11),"")} -> 케이블 정비 | AM18: =IF(AL18="","",COUNTIF(AC$8:AC$307,AL18)) -> 6 | AN18: =IF(AL18="","",COUNTIFS(AC$8:AC$307,AL18,AH$8:AH$307,">="&9)) -> 2 | AO18: =IF(AL18="","",IFERROR(ROUND(AVERAGEIFS(AH$8:AH$307,AC$8:AC$307,AL18,AH$8:AH$307,"<>"),1),"-")) -> 7.3 | AP18: =IF(AL18="","",IFERROR(ROUND(AVERAGEIFS(AK$8:AK$307,AC$8:AC$307,AL18,AK$8:AK$307,"<>"),1),"-")) -> 2.3 | AQ18: =IF(OR(AL18="",AO18="-",AP18="-"),"",IF(AO18=0,0,(AO18-AP18)/AO18)) -> 0.68493151 | AR18: =IF(AL18="","",IF(AO18="-","미입력",IF(AP18="-",IF(AO18>=9,"고위험⚠",IF(AO18>=6,"중위험⚠","저위험⚠")),IF(AO18>=9,"고위험",IF(AO18>=6,"중위험","저위험"))))) -> 중위험
A19: 12 | B19: 기계설비 | C19: 80 | D19: 해당 | H19: 위험성평가 참여자 명단 | Z19: 기타건설장비 | AB19: 4-3 | AC19: 접지 점검 | AD19: 측정기 리드선 접촉 불량 | AE19: 측정기 교정 확인, 리드선 상태 점검 | AF19: 2 | AG19: 3 | AH19: =IF(AND(AF19<>"",AG19<>""),AF19*AG19,"") -> 6 | AI19: 1 | AJ19: 3 | AK19: =IF(AND(AI19<>"",AJ19<>""),AI19*AJ19,"") -> 3 | AL19: {=IFERROR(INDEX(_xlfn._xlws.SORT(_xlfn.UNIQUE(_xlfn._xlws.FILTER(AC$8:AC$307,AC$8:AC$307<>""))),12),"")} | AM19: =IF(AL19="","",COUNTIF(AC$8:AC$307,AL19)) | AN19: =IF(AL19="","",COUNTIFS(AC$8:AC$307,AL19,AH$8:AH$307,">="&9)) | AO19: =IF(AL19="","",IFERROR(ROUND(AVERAGEIFS(AH$8:AH$307,AC$8:AC$307,AL19,AH$8:AH$307,"<>"),1),"-")) | AP19: =IF(AL19="","",IFERROR(ROUND(AVERAGEIFS(AK$8:AK$307,AC$8:AC$307,AL19,AK$8:AK$307,"<>"),1),"-")) | AQ19: =IF(OR(AL19="",AO19="-",AP19="-"),"",IF(AO19=0,0,(AO19-AP19)/AO19)) | AR19: =IF(AL19="","",IF(AO19="-","미입력",IF(AP19="-",IF(AO19>=9,"고위험⚠",IF(AO19>=6,"중위험⚠","저위험⚠")),IF(AO19>=9,"고위험",IF(AO19>=6,"중위험","저위험")))))
A20: 13 | B20: 트럭 | C20: 76 | D20: 미해당 | E20: 중장비 | H20: 순번 | I20: 소 속 | J20: 성 명 | O20: 대시보드 입력시트의 동작 내용을 프롬프트로 만들어줘! 위험성평가 입력 셀이 있고, 기인물은 (a7 테이블) 드롭박스로 선택을 하면 작업문류 테이블에서 10개의 구분작업중에 결과가 해당으로 표기가 되고(H7 테이블) H20에서 참여자 명단을 입력하고, 그리고 O7테이블에 노란셀부분 입력하고, 회색셀은 앞에서 선택, 입력에 따라 자동반영되고, 추가로 입력해야되는 부분은 노랑셀에 입력함 그리고 U7테이블에서는 단계와 공정을 입력하고 노란란셀에..SIF 기인물 테이블에서 선택을 하면 Z7에 나타나고 U7 테이블 기인물 열에 셀에서 선택을 하던가 입력을 직접 할수도 있고, AB7 테이블에서는 행방향으로 DB 타입으로 입력해 나갈수 있고 V7열에 정보를 입력한게 AC7열에서는 드롭다운으로 선택하게하고, 유해위험요인, 안전조치사항, 가능성 중대성 위험도는 각각 직접 입력하게 하고AL7 테이블에서는 자동으로 고위험 중위험 저위험등으로 고위험공정이 식별되게 하고, 차트로도 표시가 되는 것이 핵심 동작알고리즘인데, 이부분을 웹으로 만들수 있도록 너가 프롬프트를 만들어줘! 지금 시트를 기반으로 해서! | Z20: 계단 | AB20: 5-1 | AC20: 새 배전반 설치 | AD20: 무거운 배전반 운반 중 근골격계 질환 | AE20: 운반기구 사용, 2인 1조 작업 | AF20: 3 | AG20: 3 | AH20: =IF(AND(AF20<>"",AG20<>""),AF20*AG20,"") -> 9 | AI20: 2 | AJ20: 1 | AK20: =IF(AND(AI20<>"",AJ20<>""),AI20*AJ20,"") -> 2 | AL20: {=IFERROR(INDEX(_xlfn._xlws.SORT(_xlfn.UNIQUE(_xlfn._xlws.FILTER(AC$8:AC$307,AC$8:AC$307<>""))),13),"")} | AM20: =IF(AL20="","",COUNTIF(AC$8:AC$307,AL20)) | AN20: =IF(AL20="","",COUNTIFS(AC$8:AC$307,AL20,AH$8:AH$307,">="&9)) | AO20: =IF(AL20="","",IFERROR(ROUND(AVERAGEIFS(AH$8:AH$307,AC$8:AC$307,AL20,AH$8:AH$307,"<>"),1),"-")) | AP20: =IF(AL20="","",IFERROR(ROUND(AVERAGEIFS(AK$8:AK$307,AC$8:AC$307,AL20,AK$8:AK$307,"<>"),1),"-")) | AQ20: =IF(OR(AL20="",AO20="-",AP20="-"),"",IF(AO20=0,0,(AO20-AP20)/AO20)) | AR20: =IF(AL20="","",IF(AO20="-","미입력",IF(AP20="-",IF(AO20>=9,"고위험⚠",IF(AO20>=6,"중위험⚠","저위험⚠")),IF(AO20>=9,"고위험",IF(AO20>=6,"중위험","저위험")))))
A21: 14 | B21: 달비계 | C21: 70 | D21: 미해당 | F21: 고소 | H21: 1 | I21: 삼지전자 | J21: 김가나1 | Z21: 천공기/항타기 | AB21: 5-2 | AC21: 새 배전반 설치 | AD21: 설치 위치 조정 시 끼임 위험 | AE21: 안전간격 확보, 끼임방지 커버 설치 | AF21: 2 | AG21: 4 | AH21: =IF(AND(AF21<>"",AG21<>""),AF21*AG21,"") -> 8 | AI21: 1 | AJ21: 3 | AK21: =IF(AND(AI21<>"",AJ21<>""),AI21*AJ21,"") -> 3 | AL21: {=IFERROR(INDEX(_xlfn._xlws.SORT(_xlfn.UNIQUE(_xlfn._xlws.FILTER(AC$8:AC$307,AC$8:AC$307<>""))),14),"")} | AM21: =IF(AL21="","",COUNTIF(AC$8:AC$307,AL21)) | AN21: =IF(AL21="","",COUNTIFS(AC$8:AC$307,AL21,AH$8:AH$307,">="&9)) | AO21: =IF(AL21="","",IFERROR(ROUND(AVERAGEIFS(AH$8:AH$307,AC$8:AC$307,AL21,AH$8:AH$307,"<>"),1),"-")) | AP21: =IF(AL21="","",IFERROR(ROUND(AVERAGEIFS(AK$8:AK$307,AC$8:AC$307,AL21,AK$8:AK$307,"<>"),1),"-")) | AQ21: =IF(OR(AL21="",AO21="-",AP21="-"),"",IF(AO21=0,0,(AO21-AP21)/AO21)) | AR21: =IF(AL21="","",IF(AO21="-","미입력",IF(AP21="-",IF(AO21>=9,"고위험⚠",IF(AO21>=6,"중위험⚠","저위험⚠")),IF(AO21>=9,"고위험",IF(AO21>=6,"중위험","저위험")))))
A22: 15 | B22: 이동식비계 | C22: 70 | D22: 해당 | F22: 고소 | H22: 2 | I22: 삼지전자 | J22: 김가나2 | Z22: 리프트 | AB22: 5-3 | AC22: 새 배전반 설치 | AD22: 배전반 고정 볼트 체결 시 소음 | AE22: 귀마개 착용 | AF22: 4 | AG22: 1 | AH22: =IF(AND(AF22<>"",AG22<>""),AF22*AG22,"") -> 4 | AI22: 2 | AJ22: 1 | AK22: =IF(AND(AI22<>"",AJ22<>""),AI22*AJ22,"") -> 2 | AL22: {=IFERROR(INDEX(_xlfn._xlws.SORT(_xlfn.UNIQUE(_xlfn._xlws.FILTER(AC$8:AC$307,AC$8:AC$307<>""))),15),"")} | AM22: =IF(AL22="","",COUNTIF(AC$8:AC$307,AL22)) | AN22: =IF(AL22="","",COUNTIFS(AC$8:AC$307,AL22,AH$8:AH$307,">="&9)) | AO22: =IF(AL22="","",IFERROR(ROUND(AVERAGEIFS(AH$8:AH$307,AC$8:AC$307,AL22,AH$8:AH$307,"<>"),1),"-")) | AP22: =IF(AL22="","",IFERROR(ROUND(AVERAGEIFS(AK$8:AK$307,AC$8:AC$307,AL22,AK$8:AK$307,"<>"),1),"-")) | AQ22: =IF(OR(AL22="",AO22="-",AP22="-"),"",IF(AO22=0,0,(AO22-AP22)/AO22)) | AR22: =IF(AL22="","",IF(AO22="-","미입력",IF(AP22="-",IF(AO22>=9,"고위험⚠",IF(AO22>=6,"중위험⚠","저위험⚠")),IF(AO22>=9,"고위험",IF(AO22>=6,"중위험","저위험")))))
A23: 16 | B23: 충전부 | C23: 69 | D23: 미해당 | F23: 감전 | H23: 3 | I23: 삼지전자 | J23: 김가나3 | Z23: 지게차 | AB23: 6-1 | AC23: 케이블 결선 | AD23: 케이블 피복에 의한 감전 | AE23: 절연저항 측정 완료 후 결선 | AF23: 2 | AG23: 5 | AH23: =IF(AND(AF23<>"",AG23<>""),AF23*AG23,"") -> 10 | AI23: 1 | AJ23: 3 | AK23: =IF(AND(AI23<>"",AJ23<>""),AI23*AJ23,"") -> 3 | AL23: {=IFERROR(INDEX(_xlfn._xlws.SORT(_xlfn.UNIQUE(_xlfn._xlws.FILTER(AC$8:AC$307,AC$8:AC$307<>""))),16),"")} | AM23: =IF(AL23="","",COUNTIF(AC$8:AC$307,AL23)) | AN23: =IF(AL23="","",COUNTIFS(AC$8:AC$307,AL23,AH$8:AH$307,">="&9)) | AO23: =IF(AL23="","",IFERROR(ROUND(AVERAGEIFS(AH$8:AH$307,AC$8:AC$307,AL23,AH$8:AH$307,"<>"),1),"-")) | AP23: =IF(AL23="","",IFERROR(ROUND(AVERAGEIFS(AK$8:AK$307,AC$8:AC$307,AL23,AK$8:AK$307,"<>"),1),"-")) | AQ23: =IF(OR(AL23="",AO23="-",AP23="-"),"",IF(AO23=0,0,(AO23-AP23)/AO23)) | AR23: =IF(AL23="","",IF(AO23="-","미입력",IF(AP23="-",IF(AO23>=9,"고위험⚠",IF(AO23>=6,"중위험⚠","저위험⚠")),IF(AO23>=9,"고위험",IF(AO23>=6,"중위험","저위험")))))
A24: 17 | B24: 개구부(기타개구부) | C24: 67 | D24: 미해당 | F24: 고소 | H24: 4 | I24: 삼지전자 | J24: 김가나4 | Z24: 분류불능 | AB24: 6-2 | AC24: 케이블 결선 | AD24: 케이블 과부하로 화재 위험 | AE24: 케이블 용량 계산 후 적정 규격 사용 | AF24: 2 | AG24: 5 | AH24: =IF(AND(AF24<>"",AG24<>""),AF24*AG24,"") -> 10 | AI24: 2 | AJ24: 1 | AK24: =IF(AND(AI24<>"",AJ24<>""),AI24*AJ24,"") -> 2 | AL24: {=IFERROR(INDEX(_xlfn._xlws.SORT(_xlfn.UNIQUE(_xlfn._xlws.FILTER(AC$8:AC$307,AC$8:AC$307<>""))),17),"")} | AM24: =IF(AL24="","",COUNTIF(AC$8:AC$307,AL24)) | AN24: =IF(AL24="","",COUNTIFS(AC$8:AC$307,AL24,AH$8:AH$307,">="&9)) | AO24: =IF(AL24="","",IFERROR(ROUND(AVERAGEIFS(AH$8:AH$307,AC$8:AC$307,AL24,AH$8:AH$307,"<>"),1),"-")) | AP24: =IF(AL24="","",IFERROR(ROUND(AVERAGEIFS(AK$8:AK$307,AC$8:AC$307,AL24,AK$8:AK$307,"<>"),1),"-")) | AQ24: =IF(OR(AL24="",AO24="-",AP24="-"),"",IF(AO24=0,0,(AO24-AP24)/AO24)) | AR24: =IF(AL24="","",IF(AO24="-","미입력",IF(AP24="-",IF(AO24>=9,"고위험⚠",IF(AO24>=6,"중위험⚠","저위험⚠")),IF(AO24>=9,"고위험",IF(AO24>=6,"중위험","저위험")))))
A25: 18 | B25: 토사 | C25: 65 | D25: 해당 | H25: 5 | I25: 삼지전자 | J25: 김가나5 | Z25: 원인미상 | AB25: 6-3 | AC25: 케이블 결선 | AD25: 결선 단자 조임 불량으로 발열 | AE25: 토크 렌치로 규정 체결력 확인 | AF25: 3 | AG25: 4 | AH25: =IF(AND(AF25<>"",AG25<>""),AF25*AG25,"") -> 12 | AI25: 1 | AJ25: 3 | AK25: =IF(AND(AI25<>"",AJ25<>""),AI25*AJ25,"") -> 3 | AL25: {=IFERROR(INDEX(_xlfn._xlws.SORT(_xlfn.UNIQUE(_xlfn._xlws.FILTER(AC$8:AC$307,AC$8:AC$307<>""))),18),"")} | AM25: =IF(AL25="","",COUNTIF(AC$8:AC$307,AL25)) | AN25: =IF(AL25="","",COUNTIFS(AC$8:AC$307,AL25,AH$8:AH$307,">="&9)) | AO25: =IF(AL25="","",IFERROR(ROUND(AVERAGEIFS(AH$8:AH$307,AC$8:AC$307,AL25,AH$8:AH$307,"<>"),1),"-")) | AP25: =IF(AL25="","",IFERROR(ROUND(AVERAGEIFS(AK$8:AK$307,AC$8:AC$307,AL25,AK$8:AK$307,"<>"),1),"-")) | AQ25: =IF(OR(AL25="",AO25="-",AP25="-"),"",IF(AO25=0,0,(AO25-AP25)/AO25)) | AR25: =IF(AL25="","",IF(AO25="-","미입력",IF(AP25="-",IF(AO25>=9,"고위험⚠",IF(AO25>=6,"중위험⚠","저위험⚠")),IF(AO25>=9,"고위험",IF(AO25>=6,"중위험","저위험")))))
A26: 19 | B26: 기타자재(내부마감재,시멘트,마대) | C26: 63 | D26: 해당 | H26: 6 | I26: 삼지전자 | J26: 김가나6 | AB26: 7-1 | AC26: 시운전 및 점검 | AD26: 전원 투입 시 아크플래시 | AE26: 안면보호구 착용, 안전거리 확보 | AF26: 3 | AG26: 5 | AH26: =IF(AND(AF26<>"",AG26<>""),AF26*AG26,"") -> 15 | AI26: 2 | AJ26: 1 | AK26: =IF(AND(AI26<>"",AJ26<>""),AI26*AJ26,"") -> 2 | AL26: {=IFERROR(INDEX(_xlfn._xlws.SORT(_xlfn.UNIQUE(_xlfn._xlws.FILTER(AC$8:AC$307,AC$8:AC$307<>""))),19),"")} | AM26: =IF(AL26="","",COUNTIF(AC$8:AC$307,AL26)) | AN26: =IF(AL26="","",COUNTIFS(AC$8:AC$307,AL26,AH$8:AH$307,">="&9)) | AO26: =IF(AL26="","",IFERROR(ROUND(AVERAGEIFS(AH$8:AH$307,AC$8:AC$307,AL26,AH$8:AH$307,"<>"),1),"-")) | AP26: =IF(AL26="","",IFERROR(ROUND(AVERAGEIFS(AK$8:AK$307,AC$8:AC$307,AL26,AK$8:AK$307,"<>"),1),"-")) | AQ26: =IF(OR(AL26="",AO26="-",AP26="-"),"",IF(AO26=0,0,(AO26-AP26)/AO26)) | AR26: =IF(AL26="","",IF(AO26="-","미입력",IF(AP26="-",IF(AO26>=9,"고위험⚠",IF(AO26>=6,"중위험⚠","저위험⚠")),IF(AO26>=9,"고위험",IF(AO26>=6,"중위험","저위험")))))
A27: 20 | B27: 이동식크레인 | C27: 61 | D27: 해당 | E27: 중장비 | H27: 7 | I27: 삼지전자 | J27: 김가나7 | AB27: 7-2 | AC27: 시운전 및 점검 | AD27: 보호장치 미작동으로 사고 | AE27: 보호장치 동작 시험 완료 후 전원 투입 | AF27: 2 | AG27: 5 | AH27: =IF(AND(AF27<>"",AG27<>""),AF27*AG27,"") -> 10 | AI27: 2 | AJ27: 1 | AK27: =IF(AND(AI27<>"",AJ27<>""),AI27*AJ27,"") -> 2 | AL27: {=IFERROR(INDEX(_xlfn._xlws.SORT(_xlfn.UNIQUE(_xlfn._xlws.FILTER(AC$8:AC$307,AC$8:AC$307<>""))),20),"")} | AM27: =IF(AL27="","",COUNTIF(AC$8:AC$307,AL27)) | AN27: =IF(AL27="","",COUNTIFS(AC$8:AC$307,AL27,AH$8:AH$307,">="&9)) | AO27: =IF(AL27="","",IFERROR(ROUND(AVERAGEIFS(AH$8:AH$307,AC$8:AC$307,AL27,AH$8:AH$307,"<>"),1),"-")) | AP27: =IF(AL27="","",IFERROR(ROUND(AVERAGEIFS(AK$8:AK$307,AC$8:AC$307,AL27,AK$8:AK$307,"<>"),1),"-")) | AQ27: =IF(OR(AL27="",AO27="-",AP27="-"),"",IF(AO27=0,0,(AO27-AP27)/AO27)) | AR27: =IF(AL27="","",IF(AO27="-","미입력",IF(AP27="-",IF(AO27>=9,"고위험⚠",IF(AO27>=6,"중위험⚠","저위험⚠")),IF(AO27>=9,"고위험",IF(AO27>=6,"중위험","저위험")))))
A28: 21 | B28: 화학물질 | C28: 50 | D28: 미해당 | H28: 8 | I28: 삼지전자 | J28: 김가나8 | AB28: 1-1 | AC28: 전원차단 | AD28: 차단기 오조작으로 감전 | AE28: LOTO 절차 준수, 검전기 확인 | AF28: 2 | AG28: 5 | AH28: =IF(AND(AF28<>"",AG28<>""),AF28*AG28,"") -> 10 | AI28: 2 | AJ28: 1 | AK28: =IF(AND(AI28<>"",AJ28<>""),AI28*AJ28,"") -> 2 | AL28: {=IFERROR(INDEX(_xlfn._xlws.SORT(_xlfn.UNIQUE(_xlfn._xlws.FILTER(AC$8:AC$307,AC$8:AC$307<>""))),21),"")} | AM28: =IF(AL28="","",COUNTIF(AC$8:AC$307,AL28)) | AN28: =IF(AL28="","",COUNTIFS(AC$8:AC$307,AL28,AH$8:AH$307,">="&9)) | AO28: =IF(AL28="","",IFERROR(ROUND(AVERAGEIFS(AH$8:AH$307,AC$8:AC$307,AL28,AH$8:AH$307,"<>"),1),"-")) | AP28: =IF(AL28="","",IFERROR(ROUND(AVERAGEIFS(AK$8:AK$307,AC$8:AC$307,AL28,AK$8:AK$307,"<>"),1),"-")) | AQ28: =IF(OR(AL28="",AO28="-",AP28="-"),"",IF(AO28=0,0,(AO28-AP28)/AO28)) | AR28: =IF(AL28="","",IF(AO28="-","미입력",IF(AP28="-",IF(AO28>=9,"고위험⚠",IF(AO28>=6,"중위험⚠","저위험⚠")),IF(AO28>=9,"고위험",IF(AO28>=6,"중위험","저위험")))))
A29: 22 | B29: 기타구조물 | C29: 47 | D29: 미해당 | H29: 9 | I29: 삼지전자 | J29: 김가나9 | AB29: 1-2 | AC29: 전원차단 | AD29: 아크플래시 발생 | AE29: 절연장갑 착용, 안면보호구 | AF29: 2 | AG29: 4 | AH29: =IF(AND(AF29<>"",AG29<>""),AF29*AG29,"") -> 8 | AI29: 1 | AJ29: 3 | AK29: =IF(AND(AI29<>"",AJ29<>""),AI29*AJ29,"") -> 3 | AL29: {=IFERROR(INDEX(_xlfn._xlws.SORT(_xlfn.UNIQUE(_xlfn._xlws.FILTER(AC$8:AC$307,AC$8:AC$307<>""))),22),"")} | AM29: =IF(AL29="","",COUNTIF(AC$8:AC$307,AL29)) | AN29: =IF(AL29="","",COUNTIFS(AC$8:AC$307,AL29,AH$8:AH$307,">="&9)) | AO29: =IF(AL29="","",IFERROR(ROUND(AVERAGEIFS(AH$8:AH$307,AC$8:AC$307,AL29,AH$8:AH$307,"<>"),1),"-")) | AP29: =IF(AL29="","",IFERROR(ROUND(AVERAGEIFS(AK$8:AK$307,AC$8:AC$307,AL29,AK$8:AK$307,"<>"),1),"-")) | AQ29: =IF(OR(AL29="",AO29="-",AP29="-"),"",IF(AO29=0,0,(AO29-AP29)/AO29)) | AR29: =IF(AL29="","",IF(AO29="-","미입력",IF(AP29="-",IF(AO29>=9,"고위험⚠",IF(AO29>=6,"중위험⚠","저위험⚠")),IF(AO29>=9,"고위험",IF(AO29>=6,"중위험","저위험")))))
A30: 23 | B30: 각재(파이프,강관,합판) | C30: 39 | D30: 미해당 | H30: 10 | I30: 삼지전자 | J30: 김가나10 | AB30: 1-3 | AC30: 전원차단 | AD30: 잔류전압에 의한 감전 | AE30: 콘덴서 방전 후 작업 시작 | AF30: 3 | AG30: 5 | AH30: =IF(AND(AF30<>"",AG30<>""),AF30*AG30,"") -> 15 | AI30: 2 | AJ30: 1 | AK30: =IF(AND(AI30<>"",AJ30<>""),AI30*AJ30,"") -> 2 | AL30: {=IFERROR(INDEX(_xlfn._xlws.SORT(_xlfn.UNIQUE(_xlfn._xlws.FILTER(AC$8:AC$307,AC$8:AC$307<>""))),23),"")} | AM30: =IF(AL30="","",COUNTIF(AC$8:AC$307,AL30)) | AN30: =IF(AL30="","",COUNTIFS(AC$8:AC$307,AL30,AH$8:AH$307,">="&9)) | AO30: =IF(AL30="","",IFERROR(ROUND(AVERAGEIFS(AH$8:AH$307,AC$8:AC$307,AL30,AH$8:AH$307,"<>"),1),"-")) | AP30: =IF(AL30="","",IFERROR(ROUND(AVERAGEIFS(AK$8:AK$307,AC$8:AC$307,AL30,AK$8:AK$307,"<>"),1),"-")) | AQ30: =IF(OR(AL30="",AO30="-",AP30="-"),"",IF(AO30=0,0,(AO30-AP30)/AO30)) | AR30: =IF(AL30="","",IF(AO30="-","미입력",IF(AP30="-",IF(AO30>=9,"고위험⚠",IF(AO30>=6,"중위험⚠","저위험⚠")),IF(AO30>=9,"고위험",IF(AO30>=6,"중위험","저위험")))))
A31: 24 | B31: 철골(철골자재) | C31: 38 | D31: 해당 | F31: 고소 | H31: 11 | I31: 삼지전자 | J31: 김가나11 | AB31: 2-1 | AC31: 배전반 해체 | AD31: 볼트 풀림 시 날카로운 모서리에 절상 | AE31: 절연장갑 및 안전장갑 착용 | AF31: 3 | AG31: 2 | AH31: =IF(AND(AF31<>"",AG31<>""),AF31*AG31,"") -> 6 | AI31: 1 | AJ31: 3 | AK31: =IF(AND(AI31<>"",AJ31<>""),AI31*AJ31,"") -> 3 | AL31: {=IFERROR(INDEX(_xlfn._xlws.SORT(_xlfn.UNIQUE(_xlfn._xlws.FILTER(AC$8:AC$307,AC$8:AC$307<>""))),24),"")} | AM31: =IF(AL31="","",COUNTIF(AC$8:AC$307,AL31)) | AN31: =IF(AL31="","",COUNTIFS(AC$8:AC$307,AL31,AH$8:AH$307,">="&9)) | AO31: =IF(AL31="","",IFERROR(ROUND(AVERAGEIFS(AH$8:AH$307,AC$8:AC$307,AL31,AH$8:AH$307,"<>"),1),"-")) | AP31: =IF(AL31="","",IFERROR(ROUND(AVERAGEIFS(AK$8:AK$307,AC$8:AC$307,AL31,AK$8:AK$307,"<>"),1),"-")) | AQ31: =IF(OR(AL31="",AO31="-",AP31="-"),"",IF(AO31=0,0,(AO31-AP31)/AO31)) | AR31: =IF(AL31="","",IF(AO31="-","미입력",IF(AP31="-",IF(AO31>=9,"고위험⚠",IF(AO31>=6,"중위험⚠","저위험⚠")),IF(AO31>=9,"고위험",IF(AO31>=6,"중위험","저위험")))))
A32: 25 | B32: 벽체 | C32: 38 | D32: 해당 | H32: 12 | I32: 삼지전자 | J32: 김가나12 | AB32: 2-2 | AC32: 배전반 해체 | AD32: 배전반 넘어짐으로 충돌 | AE32: 작업반경 정리정돈, 바닥 전선 정리 | AF32: 2 | AG32: 3 | AH32: =IF(AND(AF32<>"",AG32<>""),AF32*AG32,"") -> 6 | AI32: 2 | AJ32: 1 | AK32: =IF(AND(AI32<>"",AJ32<>""),AI32*AJ32,"") -> 2 | AL32: {=IFERROR(INDEX(_xlfn._xlws.SORT(_xlfn.UNIQUE(_xlfn._xlws.FILTER(AC$8:AC$307,AC$8:AC$307<>""))),25),"")} | AM32: =IF(AL32="","",COUNTIF(AC$8:AC$307,AL32)) | AN32: =IF(AL32="","",COUNTIFS(AC$8:AC$307,AL32,AH$8:AH$307,">="&9)) | AO32: =IF(AL32="","",IFERROR(ROUND(AVERAGEIFS(AH$8:AH$307,AC$8:AC$307,AL32,AH$8:AH$307,"<>"),1),"-")) | AP32: =IF(AL32="","",IFERROR(ROUND(AVERAGEIFS(AK$8:AK$307,AC$8:AC$307,AL32,AK$8:AK$307,"<>"),1),"-")) | AQ32: =IF(OR(AL32="",AO32="-",AP32="-"),"",IF(AO32=0,0,(AO32-AP32)/AO32)) | AR32: =IF(AL32="","",IF(AO32="-","미입력",IF(AP32="-",IF(AO32>=9,"고위험⚠",IF(AO32>=6,"중위험⚠","저위험⚠")),IF(AO32>=9,"고위험",IF(AO32>=6,"중위험","저위험")))))
A33: 26 | B33: 기타건설장비 | C33: 32 | D33: 해당 | E33: 중장비 | H33: 13 | I33: 삼지전자 | J33: 김가나13 | AB33: 2-3 | AC33: 배전반 해체 | AD33: 부품 낙하로 인한 부상 | AE33: 헬멧 착용, 낙하방지망 설치 | AF33: 2 | AG33: 3 | AH33: =IF(AND(AF33<>"",AG33<>""),AF33*AG33,"") -> 6 | AI33: 1 | AJ33: 3 | AK33: =IF(AND(AI33<>"",AJ33<>""),AI33*AJ33,"") -> 3 | AL33: {=IFERROR(INDEX(_xlfn._xlws.SORT(_xlfn.UNIQUE(_xlfn._xlws.FILTER(AC$8:AC$307,AC$8:AC$307<>""))),26),"")} | AM33: =IF(AL33="","",COUNTIF(AC$8:AC$307,AL33)) | AN33: =IF(AL33="","",COUNTIFS(AC$8:AC$307,AL33,AH$8:AH$307,">="&9)) | AO33: =IF(AL33="","",IFERROR(ROUND(AVERAGEIFS(AH$8:AH$307,AC$8:AC$307,AL33,AH$8:AH$307,"<>"),1),"-")) | AP33: =IF(AL33="","",IFERROR(ROUND(AVERAGEIFS(AK$8:AK$307,AC$8:AC$307,AL33,AK$8:AK$307,"<>"),1),"-")) | AQ33: =IF(OR(AL33="",AO33="-",AP33="-"),"",IF(AO33=0,0,(AO33-AP33)/AO33)) | AR33: =IF(AL33="","",IF(AO33="-","미입력",IF(AP33="-",IF(AO33>=9,"고위험⚠",IF(AO33>=6,"중위험⚠","저위험⚠")),IF(AO33>=9,"고위험",IF(AO33>=6,"중위험","저위험")))))
A34: 27 | B34: 고정식크레인 | C34: 32 | D34: 미해당 | E34: 중장비 | H34: 14 | I34: 삼지전자 | J34: 김가나14 | AB34: 3-1 | AC34: 케이블 정비 | AD34: 피복손상으로 감전 | AE34: 절연저항 측정 후 작업 | AF34: 3 | AG34: 4 | AH34: =IF(AND(AF34<>"",AG34<>""),AF34*AG34,"") -> 12 | AI34: 2 | AJ34: 1 | AK34: =IF(AND(AI34<>"",AJ34<>""),AI34*AJ34,"") -> 2 | AL34: {=IFERROR(INDEX(_xlfn._xlws.SORT(_xlfn.UNIQUE(_xlfn._xlws.FILTER(AC$8:AC$307,AC$8:AC$307<>""))),27),"")} | AM34: =IF(AL34="","",COUNTIF(AC$8:AC$307,AL34)) | AN34: =IF(AL34="","",COUNTIFS(AC$8:AC$307,AL34,AH$8:AH$307,">="&9)) | AO34: =IF(AL34="","",IFERROR(ROUND(AVERAGEIFS(AH$8:AH$307,AC$8:AC$307,AL34,AH$8:AH$307,"<>"),1),"-")) | AP34: =IF(AL34="","",IFERROR(ROUND(AVERAGEIFS(AK$8:AK$307,AC$8:AC$307,AL34,AK$8:AK$307,"<>"),1),"-")) | AQ34: =IF(OR(AL34="",AO34="-",AP34="-"),"",IF(AO34=0,0,(AO34-AP34)/AO34)) | AR34: =IF(AL34="","",IF(AO34="-","미입력",IF(AP34="-",IF(AO34>=9,"고위험⚠",IF(AO34>=6,"중위험⚠","저위험⚠")),IF(AO34>=9,"고위험",IF(AO34>=6,"중위험","저위험")))))
A35: 28 | B35: 계단 | C35: 32 | D35: 해당 | F35: 고소 | H35: 15 | I35: 삼지전자 | J35: 김가나15 | AB35: 3-2 | AC35: 케이블 정비 | AD35: 케이블 단선 처리 시 천공 | AE35: 단선 케이블 처리함 사용, 분리 보관 | AF35: 2 | AG35: 2 | AH35: =IF(AND(AF35<>"",AG35<>""),AF35*AG35,"") -> 4 | AI35: 1 | AJ35: 3 | AK35: =IF(AND(AI35<>"",AJ35<>""),AI35*AJ35,"") -> 3 | AL35: {=IFERROR(INDEX(_xlfn._xlws.SORT(_xlfn.UNIQUE(_xlfn._xlws.FILTER(AC$8:AC$307,AC$8:AC$307<>""))),28),"")} | AM35: =IF(AL35="","",COUNTIF(AC$8:AC$307,AL35)) | AN35: =IF(AL35="","",COUNTIFS(AC$8:AC$307,AL35,AH$8:AH$307,">="&9)) | AO35: =IF(AL35="","",IFERROR(ROUND(AVERAGEIFS(AH$8:AH$307,AC$8:AC$307,AL35,AH$8:AH$307,"<>"),1),"-")) | AP35: =IF(AL35="","",IFERROR(ROUND(AVERAGEIFS(AK$8:AK$307,AC$8:AC$307,AL35,AK$8:AK$307,"<>"),1),"-")) | AQ35: =IF(OR(AL35="",AO35="-",AP35="-"),"",IF(AO35=0,0,(AO35-AP35)/AO35)) | AR35: =IF(AL35="","",IF(AO35="-","미입력",IF(AP35="-",IF(AO35>=9,"고위험⚠",IF(AO35>=6,"중위험⚠","저위험⚠")),IF(AO35>=9,"고위험",IF(AO35>=6,"중위험","저위험")))))
A36: 29 | B36: 전주 | C36: 32 | D36: 미해당 | H36: 16 | I36: 삼지전자 | J36: 김가나16 | AB36: 3-3 | AC36: 케이블 정비 | AD36: 케이블 트레이 날카로운 부분에 절상 | AE36: 안전장갑 착용, 날카로운 부분 테이핑 | AF36: 3 | AG36: 2 | AH36: =IF(AND(AF36<>"",AG36<>""),AF36*AG36,"") -> 6 | AI36: 2 | AJ36: 1 | AK36: =IF(AND(AI36<>"",AJ36<>""),AI36*AJ36,"") -> 2 | AL36: {=IFERROR(INDEX(_xlfn._xlws.SORT(_xlfn.UNIQUE(_xlfn._xlws.FILTER(AC$8:AC$307,AC$8:AC$307<>""))),29),"")} | AM36: =IF(AL36="","",COUNTIF(AC$8:AC$307,AL36)) | AN36: =IF(AL36="","",COUNTIFS(AC$8:AC$307,AL36,AH$8:AH$307,">="&9)) | AO36: =IF(AL36="","",IFERROR(ROUND(AVERAGEIFS(AH$8:AH$307,AC$8:AC$307,AL36,AH$8:AH$307,"<>"),1),"-")) | AP36: =IF(AL36="","",IFERROR(ROUND(AVERAGEIFS(AK$8:AK$307,AC$8:AC$307,AL36,AK$8:AK$307,"<>"),1),"-")) | AQ36: =IF(OR(AL36="",AO36="-",AP36="-"),"",IF(AO36=0,0,(AO36-AP36)/AO36)) | AR36: =IF(AL36="","",IF(AO36="-","미입력",IF(AP36="-",IF(AO36>=9,"고위험⚠",IF(AO36>=6,"중위험⚠","저위험⚠")),IF(AO36>=9,"고위험",IF(AO36>=6,"중위험","저위험")))))
A37: 30 | B37: 철근콘크리트자재(철근,콘크리트,PC) | C37: 31 | D37: 미해당 | H37: 17 | I37: 삼지전자 | J37: 김가나17 | AB37: 4-1 | AC37: 접지 점검 | AD37: 접지저항 미확보로 감전 위험 | AE37: 접지측정기로 저항값 확인 후 작업 | AF37: 3 | AG37: 5 | AH37: =IF(AND(AF37<>"",AG37<>""),AF37*AG37,"") -> 15 | AI37: 1 | AJ37: 3 | AK37: =IF(AND(AI37<>"",AJ37<>""),AI37*AJ37,"") -> 3 | AL37: {=IFERROR(INDEX(_xlfn._xlws.SORT(_xlfn.UNIQUE(_xlfn._xlws.FILTER(AC$8:AC$307,AC$8:AC$307<>""))),30),"")} | AM37: =IF(AL37="","",COUNTIF(AC$8:AC$307,AL37)) | AN37: =IF(AL37="","",COUNTIFS(AC$8:AC$307,AL37,AH$8:AH$307,">="&9)) | AO37: =IF(AL37="","",IFERROR(ROUND(AVERAGEIFS(AH$8:AH$307,AC$8:AC$307,AL37,AH$8:AH$307,"<>"),1),"-")) | AP37: =IF(AL37="","",IFERROR(ROUND(AVERAGEIFS(AK$8:AK$307,AC$8:AC$307,AL37,AK$8:AK$307,"<>"),1),"-")) | AQ37: =IF(OR(AL37="",AO37="-",AP37="-"),"",IF(AO37=0,0,(AO37-AP37)/AO37)) | AR37: =IF(AL37="","",IF(AO37="-","미입력",IF(AP37="-",IF(AO37>=9,"고위험⚠",IF(AO37>=6,"중위험⚠","저위험⚠")),IF(AO37>=9,"고위험",IF(AO37>=6,"중위험","저위험")))))
A38: 31 | B38: 천공기/항타기 | C38: 30 | D38: 해당 | E38: 중장비 | H38: 18 | I38: 삼지전자 | J38: 김가나18 | AB38: 4-2 | AC38: 접지 점검 | AD38: 접지선 풀림으로 감전 | AE38: 접지선 체결 상태 사전 확인 | AF38: 2 | AG38: 5 | AH38: =IF(AND(AF38<>"",AG38<>""),AF38*AG38,"") -> 10 | AI38: 2 | AJ38: 1 | AK38: =IF(AND(AI38<>"",AJ38<>""),AI38*AJ38,"") -> 2 | AL38: {=IFERROR(INDEX(_xlfn._xlws.SORT(_xlfn.UNIQUE(_xlfn._xlws.FILTER(AC$8:AC$307,AC$8:AC$307<>""))),31),"")} | AM38: =IF(AL38="","",COUNTIF(AC$8:AC$307,AL38)) | AN38: =IF(AL38="","",COUNTIFS(AC$8:AC$307,AL38,AH$8:AH$307,">="&9)) | AO38: =IF(AL38="","",IFERROR(ROUND(AVERAGEIFS(AH$8:AH$307,AC$8:AC$307,AL38,AH$8:AH$307,"<>"),1),"-")) | AP38: =IF(AL38="","",IFERROR(ROUND(AVERAGEIFS(AK$8:AK$307,AC$8:AC$307,AL38,AK$8:AK$307,"<>"),1),"-")) | AQ38: =IF(OR(AL38="",AO38="-",AP38="-"),"",IF(AO38=0,0,(AO38-AP38)/AO38)) | AR38: =IF(AL38="","",IF(AO38="-","미입력",IF(AP38="-",IF(AO38>=9,"고위험⚠",IF(AO38>=6,"중위험⚠","저위험⚠")),IF(AO38>=9,"고위험",IF(AO38>=6,"중위험","저위험")))))
A39: 32 | B39: 흙막이가시설 | C39: 30 | D39: 미해당 | H39: 19 | I39: 삼지전자 | J39: 김가나19 | AB39: 4-3 | AC39: 접지 점검 | AD39: 측정기 리드선 접촉 불량 | AE39: 측정기 교정 확인, 리드선 상태 점검 | AF39: 2 | AG39: 3 | AH39: =IF(AND(AF39<>"",AG39<>""),AF39*AG39,"") -> 6 | AI39: 1 | AJ39: 3 | AK39: =IF(AND(AI39<>"",AJ39<>""),AI39*AJ39,"") -> 3 | AL39: {=IFERROR(INDEX(_xlfn._xlws.SORT(_xlfn.UNIQUE(_xlfn._xlws.FILTER(AC$8:AC$307,AC$8:AC$307<>""))),32),"")} | AM39: =IF(AL39="","",COUNTIF(AC$8:AC$307,AL39)) | AN39: =IF(AL39="","",COUNTIFS(AC$8:AC$307,AL39,AH$8:AH$307,">="&9)) | AO39: =IF(AL39="","",IFERROR(ROUND(AVERAGEIFS(AH$8:AH$307,AC$8:AC$307,AL39,AH$8:AH$307,"<>"),1),"-")) | AP39: =IF(AL39="","",IFERROR(ROUND(AVERAGEIFS(AK$8:AK$307,AC$8:AC$307,AL39,AK$8:AK$307,"<>"),1),"-")) | AQ39: =IF(OR(AL39="",AO39="-",AP39="-"),"",IF(AO39=0,0,(AO39-AP39)/AO39)) | AR39: =IF(AL39="","",IF(AO39="-","미입력",IF(AP39="-",IF(AO39>=9,"고위험⚠",IF(AO39>=6,"중위험⚠","저위험⚠")),IF(AO39>=9,"고위험",IF(AO39>=6,"중위험","저위험")))))
A40: 33 | B40: 수목 | C40: 25 | D40: 미해당 | H40: 20 | I40: 삼지전자 | J40: 김가나20 | AB40: 5-1 | AC40: 새 배전반 설치 | AD40: 무거운 배전반 운반 중 근골격계 질환 | AE40: 운반기구 사용, 2인 1조 작업 | AF40: 3 | AG40: 3 | AH40: =IF(AND(AF40<>"",AG40<>""),AF40*AG40,"") -> 9 | AI40: 2 | AJ40: 1 | AK40: =IF(AND(AI40<>"",AJ40<>""),AI40*AJ40,"") -> 2 | AL40: {=IFERROR(INDEX(_xlfn._xlws.SORT(_xlfn.UNIQUE(_xlfn._xlws.FILTER(AC$8:AC$307,AC$8:AC$307<>""))),33),"")} | AM40: =IF(AL40="","",COUNTIF(AC$8:AC$307,AL40)) | AN40: =IF(AL40="","",COUNTIFS(AC$8:AC$307,AL40,AH$8:AH$307,">="&9)) | AO40: =IF(AL40="","",IFERROR(ROUND(AVERAGEIFS(AH$8:AH$307,AC$8:AC$307,AL40,AH$8:AH$307,"<>"),1),"-")) | AP40: =IF(AL40="","",IFERROR(ROUND(AVERAGEIFS(AK$8:AK$307,AC$8:AC$307,AL40,AK$8:AK$307,"<>"),1),"-")) | AQ40: =IF(OR(AL40="",AO40="-",AP40="-"),"",IF(AO40=0,0,(AO40-AP40)/AO40)) | AR40: =IF(AL40="","",IF(AO40="-","미입력",IF(AP40="-",IF(AO40>=9,"고위험⚠",IF(AO40>=6,"중위험⚠","저위험⚠")),IF(AO40>=9,"고위험",IF(AO40>=6,"중위험","저위험")))))
...

Sheet 기인물 위험정보제공
B1: 기인물 기반 위험성평가 — SIF DB 연계 참조 시트 | S1: {=_xlfn._xlws.FILTER(B12:B69,D12:D69="해당","—")} -> 지붕(처마,홈통)
B2: 기인물을 선택하면, 해당 기인물의 다빈도 공정 · 재해형태 · 사고사례 · 개선대책이 자동으로 표시됩니다. | 오른쪽 기인물 목록 참조 | S2: 사다리
A3: 기인물 선택 | S3: 굴착기
A4: ① 기인물 선택 | C4: 내용 | F4: 위험성평가 한줄 커멘트 | S4: 개구부(바닥개구부)
A5: 기인물 선택 | C5: 계단 | F5: =IF(C5="","","기인물 "&""&C5&"는 "&G23&", "&G24&", "&G25&" 등에 대한 위험요인과 그에 따른 대책 검토가 필요합니다. 사고사망사례와 주요 개선대책을 참조해주신 후 위험성평가에 반영해주시고, TBM 시에도 사고사망사례와 개선대책을 전달해 주시기 바랍니다.") -> 기인물 계단는 떨어짐 (28건), 부딪힘 접촉 (2건), 깔림 뒤집힘 (1건) 등에 대한 위험요인과 그에 따른 대책 검토가 필요합니다. 사고사망사례와 주요 개선대책을 참조해주신 후 위험성평가에 반영해주시고, TBM 시에도 사고사망사례와 개선대책을 전달해 주시기 바랍니다. | S5: 기계설비
A6: 기인물 분류 | C6: =IF(C5="","—",IFERROR(INDEX('SIF DB'!F$2:F$2575,MATCH(C5,'SIF DB'!G$2:G$2575,0)),"—")) -> 계단 | S6: 이동식비계
A7: ⚠ SIF 사고사망(건) | C7: =IF(C5="","—",COUNTIF('SIF DB'!G$2:G$2575,C5)) -> 32 | S7: 토사
A8: 기인물의 위험도 순위 | C8: =IF(C5="","—",IFERROR(INDEX(A$12:A$70,MATCH(C5,B$12:B$70,0))&"위","—")) -> 28위 | S8: 기타자재(내부마감재,시멘트,마대)
S9: 이동식크레인
A10: 📋 기인물 전체 목록 (다빈도순) | F10: 위험성평가 주요 검토 사항 | L10: 재해형태별 사고사망사례 | P10: 개선대책 참조용 | S10: 철골(철골자재) | AA10: ② 다빈도 사용공정 Top 10
